Workbook

Sheet FDX
A1: 46071 | D1: GARCH Model (linked model) | H1: Mohanad Assali
A2: GARCH | B2: FDX
B4: Unconditional Variance | C4: =_xlfn.VAR.P(D16:D2056) -> 0.00048628536
B5: Omega ω | C5: 0.03007671
B6: Alpha α | C6: 0.099442289
B7: Beta β | C7: 0.90563654 | D7: figures can be found using the solver function in excel
G10: LOG L | H10: =SUM(H17:H257) -> -72.930898
B12: Daily Close price 2018-2026 | M12: Annualized Variance | P12: =C5+(C6*(E2056^2))+(C7*G2056) -> 0.14410118
B13: Date | C13: FDX | D13: Returns | E13: Return^2*252 | F13: Lagged | G13: Conditional Var | H13: Log likelihood | M13: Annualized Volatility | P13: =SQRT(P12) -> 0.37960661
M14: Daily Volatility | P14: =P13/SQRT(252) -> 0.023912969
B15: 43102 | C15: 224.5699
B16: 43103 | C16: 227.37703 | D16: =(C16-C15)/C15 -> 0.012500023 | E16: =D16^2*252 -> 0.039375144
B17: 43104 | C17: 230.91647 | D17: =(C17-C16)/C16 -> 0.01556641 | E17: =D17^2*252 -> 0.061062903 | F17: =E16 -> 0.039375144 | G17: =C4 -> 0.00048628536 | H17: =LN((1/SQRT(2*PI()*G17))*EXP(-0.5*E17/G17)) -> -59.889633
B18: 43105 | C18: 231.82309 | D18: =(C18-C17)/C17 -> 0.0039261652 | E18: =D18^2*252 -> 0.0038845227 | F18: =E17 -> 0.061062903 | G18: =($C$5+$C$6)*F17+($C$7*G17) -> 0.0055402271 | H18: =LN((1/SQRT(2*PI()*G18))*EXP(-0.5*E18/G18)) -> 1.328347
B19: 43108 | C19: 234.21175 | D19: =(C19-C18)/C18 -> 0.010303791 | E19: =D19^2*252 -> 0.026754362 | F19: =E18 -> 0.0038845227 | G19: =($C$5+$C$6)*F18+($C$7*G18) -> 0.012926238 | H19: =LN((1/SQRT(2*PI()*G19))*EXP(-0.5*E19/G19)) -> 0.22042363
B20: 43109 | C20: 233.41849 | D20: =(C20-C19)/C19 -> -0.0033869295 | E20: =D20^2*252 -> 0.0028907654 | F20: =E19 -> 0.026754362 | G20: =($C$5+$C$6)*F19+($C$7*G19) -> 0.012209593 | H20: =LN((1/SQRT(2*PI()*G20))*EXP(-0.5*E20/G20)) -> 1.1654472
B21: 43110 | C21: 233.64519 | D21: =(C21-C20)/C20 -> 0.00097121625 | E21: =D21^2*252 -> 0.00023770178 | F21: =E20 -> 0.0028907654 | G21: =($C$5+$C$6)*F20+($C$7*G20) -> 0.014522652 | H21: =LN((1/SQRT(2*PI()*G21))*EXP(-0.5*E21/G21)) -> 1.1889005
B22: 43111 | C22: 236.41742 | D22: =(C22-C21)/C21 -> 0.011865137 | E22: =D22^2*252 -> 0.035476929 | F22: =E21 -> 0.00023770178 | G22: =($C$5+$C$6)*F21+($C$7*G21) -> 0.013526653 | H22: =LN((1/SQRT(2*PI()*G22))*EXP(-0.5*E22/G22)) -> -0.0787632
B23: 43112 | C23: 236.99281 | D23: =(C23-C22)/C22 -> 0.0024338041 | E23: =D23^2*252 -> 0.0014926974 | F23: =E22 -> 0.035476929 | G23: =($C$5+$C$6)*F22+($C$7*G22) -> 0.012281018 | H23: =LN((1/SQRT(2*PI()*G23))*EXP(-0.5*E23/G23)) -> 1.2201391
B24: 43116 | C24: 235.01384 | D24: =(C24-C23)/C23 -> -0.0083503519 | E24: =D24^2*252 -> 0.017571551 | F24: =E23 -> 0.0014926974 | G24: =($C$5+$C$6)*F23+($C$7*G23) -> 0.015717075 | H24: =LN((1/SQRT(2*PI()*G24))*EXP(-0.5*E24/G24)) -> 0.59856968
B25: 43117 | C25: 236.67888 | D25: =(C25-C24)/C24 -> 0.0070848554 | E25: =D25^2*252 -> 0.012649184 | F25: =E24 -> 0.017571551 | G25: =($C$5+$C$6)*F24+($C$7*G24) -> 0.014427291 | H25: =LN((1/SQRT(2*PI()*G25))*EXP(-0.5*E25/G25)) -> 0.76200133
B26: 43118 | C26: 237.28046 | D26: =(C26-C25)/C25 -> 0.0025417467 | E26: =D26^2*252 -> 0.00162804 | F26: =E25 -> 0.012649184 | G26: =($C$5+$C$6)*F25+($C$7*G25) -> 0.015341731 | H26: =LN((1/SQRT(2*PI()*G26))*EXP(-0.5*E26/G26)) -> 1.1165916
B27: 43119 | C27: 239.14603 | D27: =(C27-C26)/C26 -> 0.0078622997 | E27: =D27^2*252 -> 0.015577571 | F27: =E26 -> 0.00162804 | G27: =($C$5+$C$6)*F26+($C$7*G26) -> 0.015532342 | H27: =LN((1/SQRT(2*PI()*G27))*EXP(-0.5*E27/G27)) -> 0.66202094
B28: 43122 | C28: 238.77119 | D28: =(C28-C27)/C27 -> -0.0015673777 | E28: =D28^2*252 -> 0.00061908157 | F28: =E27 -> 0.015577571 | G28: =($C$5+$C$6)*F27+($C$7*G27) -> 0.014277519 | H28: =LN((1/SQRT(2*PI()*G28))*EXP(-0.5*E28/G28)) -> 1.1839157
B29: 43123 | C29: 237.14093 | D29: =(C29-C28)/C28 -> -0.006827726 | E29: =D29^2*252 -> 0.011747696 | F29: =E28 -> 0.00061908157 | G29: =($C$5+$C$6)*F28+($C$7*G28) -> 0.014947834 | H29: =LN((1/SQRT(2*PI()*G29))*EXP(-0.5*E29/G29)) -> 0.78969943
... B257: 43452 | C257: 162.97208 | D257: =(C257-C256)/C256 -> 0.015477938 | E257: =D257^2*252 -> 0.060370771 | F257: =E256 -> 0.027405812 | G257: =($C$5+$C$6)*F256+($C$7*G256) -> 0.22898981 | H257: =LN((1/SQRT(2*PI()*G257))*EXP(-0.5*E257/G257)) -> -0.31371943
B258: 43453 | C258: 143.15227 | D258: =(C258-C257)/C257 -> -0.12161475 | E258: =D258^2*252 -> 3.7271174 | F258: =E257 -> 0.060370771 | G258: =($C$5+$C$6)*F257+($C$7*G257) -> 0.21093112
B259: 43454 | C259: 140.69461 | D259: =(C259-C258)/C258 -> -0.017168131 | E259: =D259^2*252 -> 0.074275669 | F259: =E258 -> 3.7271174 | G259: =($C$5+$C$6)*F258+($C$7*G258) -> 0.19884609 | H259: =LN((1/SQRT(2*PI()*G259))*EXP(-0.5*E259/G259)) -> -0.29809318
B260: 43455 | C260: 139.17949 | D260: =(C260-C259)/C259 -> -0.010768866 | E260: =D260^2*252 -> 0.029224058 | F260: =E259 -> 0.074275669 | G260: =($C$5+$C$6)*F259+($C$7*G259) -> 0.6628148 | H260: =LN((1/SQRT(2*PI()*G260))*EXP(-0.5*E260/G260)) -> -0.73535412
B261: 43458 | C261: 134.5108 | D261: =(C261-C260)/C260 -> -0.033544353 | E261: =D261^2*252 -> 0.28355635 | F261: =E260 -> 0.029224058 | G261: =($C$5+$C$6)*F260+($C$7*G260) -> 0.60988941 | H261: =LN((1/SQRT(2*PI()*G261))*EXP(-0.5*E261/G261)) -> -0.9041651
B262: 43460 | C262: 141.07341 | D262: =(C262-C261)/C261 -> 0.048788697 | E262: =D262^2*252 -> 0.59984491 | F262: =E261 -> 0.28355635 | G262: =($C$5+$C$6)*F261+($C$7*G261) -> 0.55612321 | H262: =LN((1/SQRT(2*PI()*G262))*EXP(-0.5*E262/G262)) -> -1.1648652
B263: 43461 | C263: 141.83978 | D263: =(C263-C262)/C262 -> 0.0054324389 | E263: =D263^2*252 -> 0.0074368709 | F263: =E262 -> 0.59984491 | G263: =($C$5+$C$6)*F262+($C$7*G262) -> 0.54037143 | H263: =LN((1/SQRT(2*PI()*G263))*EXP(-0.5*E263/G263)) -> -0.61807052
B264: 43462 | C264: 140.04274 | D264: =(C264-C263)/C263 -> -0.012669526 | E264: =D264^2*252 -> 0.040450257 | F264: =E263 -> 0.0074368709 | G264: =($C$5+$C$6)*F263+($C$7*G263) -> 0.56707143 | H264: =LN((1/SQRT(2*PI()*G264))*EXP(-0.5*E264/G264)) -> -0.67096946
B265: 43465 | C265: 142.11282 | D265: =(C265-C264)/C264 -> 0.014781799 | E265: =D265^2*252 -> 0.055062398 | F265: =E264 -> 0.040450257 | G265: =($C$5+$C$6)*F264+($C$7*G264) -> 0.51452383 | H265: =LN((1/SQRT(2*PI()*G265))*EXP(-0.5*E265/G265)) -> -0.64018994
B266: 43467 | C266: 143.75124 | D266: =(C266-C265)/C265 -> 0.011528956 | E266: =D266^2*252 -> 0.03349504 | F266: =E265 -> 0.055062398 | G266: =($C$5+$C$6)*F265+($C$7*G265) -> 0.47121066 | H266: =LN((1/SQRT(2*PI()*G266))*EXP(-0.5*E266/G266)) -> -0.57825499
B267: 43468 | C267: 138.46599 | D267: =(C267-C266)/C266 -> -0.036766625 | E267: =D267^2*252 -> 0.34064975 | F267: =E266 -> 0.03349504 | G267: =($C$5+$C$6)*F266+($C$7*G266) -> 0.43387722 | H267: =LN((1/SQRT(2*PI()*G267))*EXP(-0.5*E267/G267)) -> -0.89400637
B268: 43469 | C268: 144.84354 | D268: =(C268-C267)/C267 -> 0.04605859 | E268: =D268^2*252 -> 0.53459122 | F268: =E267 -> 0.34064975 | G268: =($C$5+$C$6)*F267+($C$7*G267) -> 0.3972733 | H268: =LN((1/SQRT(2*PI()*G268))*EXP(-0.5*E268/G268)) -> -1.1301986
B269: 43472 | C269: 146.86957 | D269: =(C269-C268)/C268 -> 0.013987725 | E269: =D269^2*252 -> 0.049305423 | F269: =E268 -> 0.53459122 | G269: =($C$5+$C$6)*F268+($C$7*G268) -> 0.40390584 | H269: =LN((1/SQRT(2*PI()*G269))*EXP(-0.5*E269/G269)) -> -0.52668757
B270: 43473 | C270: 147.12502 | D270: =(C270-C269)/C269 -> 0.0017392806 | E270: =D270^2*252 -> 0.00076232443 | F270: =E269 -> 0.049305423 | G270: =($C$5+$C$6)*F269+($C$7*G269) -> 0.43503161 | H270: =LN((1/SQRT(2*PI()*G270))*EXP(-0.5*E270/G270)) -> -0.50364641
... B444: 43725 | C444: 154.43726 | D444: =(C444-C443)/C443 -> -0.0015556917 | E444: =D444^2*252 -> 0.00060988451 | F444: =E443 -> 0.0023354443 | G444: =($C$5+$C$6)*F443+($C$7*G443) -> 0.14651569 | H444: =LN((1/SQRT(2*PI()*G444))*EXP(-0.5*E444/G444)) -> 0.039291566
...

Sheet GARCH
A1: 46071 | E1: GARCH Model (linked model) | K1: Mohanad Assali
A2: GARCH | B2: Historical | L2: trading days = 252
C5: Tickers | E5: Standard Deviation | H5: Annualized Volatility | K5: Difference
E6: Daily | F6: Monthly | H6: Daily | I6: Monthly
C7: AAPL | E7: =Daily!O6 -> 0.019363339 | F7: =Monthly!O6 -> 0.082158082 | H7: =E7*SQRT(252) -> 0.30738348 | I7: =F7*SQRT(12) -> 0.28460395 | K7: =(H7-I7)/I7 -> 0.08003941
C8: CMI | E8: =Daily!P6 -> 0.018226902 | F8: =Monthly!P6 -> 0.078109895 | H8: =E8*SQRT(252) -> 0.2893431 | I8: =F8*SQRT(12) -> 0.27058061 | K8: =(H8-I8)/I8 -> 0.069341593
C9: COST | E9: =Daily!Q6 -> 0.0143284 | F9: =Monthly!Q6 -> 0.061088797 | H9: =E9*SQRT(252) -> 0.22745629 | I9: =F9*SQRT(12) -> 0.2116178 | K9: =(H9-I9)/I9 -> 0.074844801
C10: FDX | E10: =Daily!R6 -> 0.022057283 | F10: =Monthly!R6 -> 0.098229052 | H10: =E10*SQRT(252) -> 0.35014851 | I10: =F10*SQRT(12) -> 0.34027542 | K10: =(H10-I10)/I10 -> 0.029015012
C11: IBM | E11: =Daily!S6 -> 0.016756659 | F11: =Monthly!S6 -> 0.077759915 | H11: =E11*SQRT(252) -> 0.26600371 | I11: =F11*SQRT(12) -> 0.26936825 | K11: =(H11-I11)/I11 -> -0.012490472
C12: KO | E12: =Daily!T6 -> 0.012161947 | F12: =Monthly!T6 -> 0.051729292 | H12: =E12*SQRT(252) -> 0.19306492 | I12: =F12*SQRT(12) -> 0.17919552 | K12: =(H12-I12)/I12 -> 0.077398135
C13: LLY | E13: =Daily!U6 -> 0.019959626 | F13: =Monthly!U6 -> 0.085080085 | H13: =E13*SQRT(252) -> 0.31684924 | I13: =F13*SQRT(12) -> 0.29472606 | K13: =(H13-I13)/I13 -> 0.07506354
C14: MCD | E14: =Daily!V6 -> 0.013568087 | F14: =Monthly!V6 -> 0.050849489 | H14: =E14*SQRT(252) -> 0.21538671 | I14: =F14*SQRT(12) -> 0.1761478 | K14: =(H14-I14)/I14 -> 0.22276128
C15: NVDA | E15: =Daily!W6 -> 0.032188281 | F15: =Monthly!W6 -> 0.1375122 | H15: =E15*SQRT(252) -> 0.51097312 | I15: =F15*SQRT(12) -> 0.47635625 | K15: =(H15-I15)/I15 -> 0.072670132
C16: OXY | E16: =Daily!X6 -> 0.033271371 | F16: =Monthly!X6 -> 0.16166537 | H16: =E16*SQRT(252) -> 0.52816665 | I16: =F16*SQRT(12) -> 0.56002528 | K16: =(H16-I16)/I16 -> -0.056887839
C17: SPX | E17: =Daily!Y6 -> 0.012288328 | F17: =Monthly!Y6 -> 0.04715625 | H17: =E17*SQRT(252) -> 0.19507116 | I17: =F17*SQRT(12) -> 0.16335404 | K17: =(H17-I17)/I17 -> 0.1941618

Sheet Daily
A2: Daily | E2: Data fetched using python (yfinance)
O5: Standard Deviation (Daily)
O6: =STDEV(O14:O2054) -> 0.019363339 | P6: =STDEV(P14:P2054) -> 0.018226902 | Q6: =STDEV(Q14:Q2054) -> 0.0143284 | R6: =STDEV(R14:R2054) -> 0.022057283 | S6: =STDEV(S14:S2054) -> 0.016756659 | T6: =STDEV(T14:T2054) -> 0.012161947 | U6: =STDEV(U14:U2054) -> 0.019959626 | V6: =STDEV(V14:V2054) -> 0.013568087 | ... Y6: =STDEV(Y14:Y2054) -> 0.012288328
B10: Daily Close price 2018-2026 | O10: Returns d/d
B11: Date | C11: AAPL | D11: CMI | E11: COST | F11: FDX | G11: IBM | H11: KO | I11: LLY | J11: MCD | K11: NVDA | L11: OXY | M11: SPX | O11: AAPL | P11: CMI | Q11: COST | R11: FDX | S11: IBM | T11: KO | U11: LLY | V11: MCD | W11: NVDA | X11: OXY | Y11: SPX
B13: 43102 | C13: 40.304165 | D13: 143.59961 | E13: 168.49821 | F13: 224.5699 | G13: 103.41283 | H13: 35.492737 | I13: 75.026703 | J13: 143.57916 | K13: 4.9285316 | L13: 60.578079 | M13: 2695.8101
B14: 43103 | C14: 40.297165 | D14: 145.18114 | E14: 170.52028 | F14: 227.37703 | G14: 106.25542 | H14: 35.414787 | I14: 75.434265 | J14: 142.97406 | K14: 5.2528987 | L14: 61.413322 | M14: 2713.0601 | O14: =(C14-C13)/C13 -> -0.00017367856 | P14: =(D14-D13)/D13 -> 0.011013454 | Q14: =(E14-E13)/E13 -> 0.012000508 | R14: =(F14-F13)/F13 -> 0.012500023 | S14: =(G14-G13)/G13 -> 0.027487793 | T14: =(H14-H13)/H13 -> -0.0021962106 | U14: =(I14-I13)/I13 -> 0.0054322293 | V14: =(J14-J13)/J13 -> -0.0042144175 | ... Y14: =(M14-M13)/M13 -> 0.0063988188
B15: 43104 | C15: 40.484341 | D15: 147.40337 | E15: 169.19606 | F15: 230.91647 | G15: 108.40749 | H15: 35.913597 | I15: 75.770943 | J15: 143.97704 | K15: 5.2805886 | L15: 61.380558 | M15: 2723.99 | O15: =(C15-C14)/C14 -> 0.0046448863 | P15: =(D15-D14)/D14 -> 0.015306596 | Q15: =(E15-E14)/E14 -> -0.0077657552 | R15: =(F15-F14)/F14 -> 0.01556641 | S15: =(G15-G14)/G14 -> 0.020253735 | T15: =(H15-H14)/H14 -> 0.014084789 | U15: =(I15-I14)/I14 -> 0.0044631912 | V15: =(J15-J14)/J14 -> 0.007015087 | ... Y15: =(M15-M14)/M14 -> 0.0040286361
B16: 43105 | C16: 40.945271 | D16: 147.16812 | E16: 167.98816 | F16: 231.82309 | G16: 108.93707 | H16: 35.905811 | I16: 76.701233 | J16: 144.26715 | K16: 5.3253388 | L16: 61.044834 | M16: 2743.1499 | O16: =(C16-C15)/C15 -> 0.011385387 | P16: =(D16-D15)/D15 -> -0.0015959252 | Q16: =(E16-E15)/E15 -> -0.007139061 | R16: =(F16-F15)/F15 -> 0.0039261652 | S16: =(G16-G15)/G15 -> 0.0048850793 | T16: =(H16-H15)/H15 -> -0.00021679246 | U16: =(I16-I15)/I15 -> 0.012277665 | V16: =(J16-J15)/J15 -> 0.0020150113 | ... Y16: =(M16-M15)/M15 -> 0.0070337674
B17: 43108 | C17: 40.793186 | D17: 147.70337 | E17: 168.64134 | F17: 234.21175 | G17: 109.59411 | H17: 35.85125 | I17: 76.311417 | J17: 144.16765 | K17: 5.4885087 | L17: 61.568893 | M17: 2747.71 | O17: =(C17-C16)/C16 -> -0.0037143325 | P17: =(D17-D16)/D16 -> 0.003636982 | Q17: =(E17-E16)/E16 -> 0.003888268 | R17: =(F17-F16)/F16 -> 0.010303791 | S17: =(G17-G16)/G16 -> 0.0060314041 | T17: =(H17-H16)/H16 -> -0.0015195762 | U17: =(I17-I16)/I16 -> -0.0050822688 | V17: =(J17-J16)/J16 -> -0.00068971046 | ... Y17: =(M17-M16)/M16 -> 0.0016623439
B18: 43109 | C18: 40.788483 | D18: 147.57362 | E18: 166.68184 | F18: 233.41849 | G18: 109.83551 | H18: 36.030506 | I18: 76.24939 | J18: 143.84442 | K18: 5.4870272 | L18: 61.323231 | M18: 2751.29 | O18: =(C18-C17)/C17 -> -0.00011530165 | P18: =(D18-D17)/D17 -> -0.00087841925 | Q18: =(E18-E17)/E17 -> -0.011619352 | R18: =(F18-F17)/F17 -> -0.0033869295 | S18: =(G18-G17)/G17 -> 0.0022026884 | T18: =(H18-H17)/H17 -> 0.0050000053 | U18: =(I18-I17)/I17 -> -0.00081281387 | V18: =(J18-J17)/J17 -> -0.0022420212 | ... Y18: =(M18-M17)/M17 -> 0.0013029316
B19: 43110 | C19: 40.779133 | D19: 146.43819 | E19: 165.9034 | F19: 233.64519 | G19: 110.07013 | H19: 35.905811 | I19: 76.284828 | J19: 143.81953 | K19: 5.5300446 | L19: 60.799179 | M19: 2748.23 | O19: =(C19-C18)/C18 -> -0.00022922704 | P19: =(D19-D18)/D18 -> -0.0076940376 | Q19: =(E19-E18)/E18 -> -0.0046702291 | R19: =(F19-F18)/F18 -> 0.00097121625 | S19: =(G19-G18)/G18 -> 0.0021360955 | T19: =(H19-H18)/H18 -> -0.0034608125 | U19: =(I19-I18)/I18 -> 0.00046477143 | V19: =(J19-J18)/J18 -> -0.0001730139 | ... Y19: =(M19-M18)/M18 -> -0.0011122268
B20: 43111 | C20: 41.010773 | D20: 149.14702 | E20: 169.44661 | F20: 236.41742 | G20: 110.08354 | H20: 35.882416 | I20: 76.541771 | J20: 143.72008 | K20: 5.5399327 | L20: 62.08474 | M20: 2767.5601 | O20: =(C20-C19)/C19 -> 0.0056803528 | P20: =(D20-D19)/D19 -> 0.018498124 | Q20: =(E20-E19)/E19 -> 0.021357085 | R20: =(F20-F19)/F19 -> 0.011865137 | S20: =(G20-G19)/G19 -> 0.00012185391 | T20: =(H20-H19)/H19 -> -0.00065158083 | U20: =(I20-I19)/I19 -> 0.0033682025 | V20: =(J20-J19)/J19 -> -0.00069153879 | ... Y20: =(M20-M19)/M19 -> 0.0070336465
B21: 43112 | C21: 41.434261 | D21: 149.37411 | E21: 171.64767 | F21: 236.99281 | G21: 109.37288 | H21: 35.968159 | I21: 77.064529 | J21: 143.86926 | K21: 5.5127378 | L21: 62.66613 | M21: 2786.24 | O21: =(C21-C20)/C20 -> 0.010326277 | P21: =(D21-D20)/D20 -> 0.0015226356 | Q21: =(E21-E20)/E20 -> 0.012989726 | R21: =(F21-F20)/F20 -> 0.0024338041 | S21: =(G21-G20)/G20 -> -0.0064556684 | T21: =(H21-H20)/H20 -> 0.0023895535 | U21: =(I21-I20)/I20 -> 0.006829715 | V21: =(J21-J20)/J20 -> 0.001038026 | ... Y21: =(M21-M20)/M20 -> 0.006749603
B22: 43116 | C22: 41.223698 | D22: 148.05215 | E22: 171.37029 | F22: 235.01384 | G22: 109.84888 | H22: 36.26432 | I22: 75.567177 | J22: 143.96046 | K22: 5.441783 | L22: 61.634407 | M22: 2776.4199 | O22: =(C22-C21)/C21 -> -0.0050818731 | P22: =(D22-D21)/D21 -> -0.0088499969 | Q22: =(E22-E21)/E21 -> -0.0016160401 | R22: =(F22-F21)/F21 -> -0.0083503519 | S22: =(G22-G21)/G21 -> 0.0043521352 | T22: =(H22-H21)/H21 -> 0.0082339953 | U22: =(I22-I21)/I21 -> -0.019429855 | V22: =(J22-J21)/J21 -> 0.00063392125 | ... Y22: =(M22-M21)/M21 -> -0.0035244876
B23: 43117 | C23: 41.90456 | D23: 148.97672 | E23: 172.05026 | F23: 236.67888 | G23: 113.0669 | H23: 36.49033 | I23: 76.382286 | J23: 145.03795 | K23: 5.5557556 | L23: 62.117508 | M23: 2802.5601 | O23: =(C23-C22)/C22 -> 0.016516287 | P23: =(D23-D22)/D22 -> 0.0062448301 | Q23: =(E23-E22)/E22 -> 0.003967884 | R23: =(F23-F22)/F22 -> 0.0070848554 | S23: =(G23-G22)/G22 -> 0.02929495 | T23: =(H23-H22)/H22 -> 0.0062322792 | U23: =(I23-I22)/I22 -> 0.010786552 | V23: =(J23-J22)/J22 -> 0.0074845836 | ... Y23: =(M23-M22)/M22 -> 0.0094150516
B24: 43118 | C24: 41.94199 | D24: 149.00105 | E24: 171.35243 | F24: 237.28046 | G24: 113.382 | H24: 36.53709 | I24: 76.036728 | J24: 144.69815 | K24: 5.5488334 | L24: 61.732662 | M24: 2798.03 | O24: =(C24-C23)/C23 -> 0.00089321567 | P24: =(D24-D23)/D23 -> 0.00016336626 | Q24: =(E24-E23)/E23 -> -0.0040559671 | R24: =(F24-F23)/F23 -> 0.0025417467 | S24: =(G24-G23)/G23 -> 0.00278686 | T24: =(H24-H23)/H23 -> 0.0012814507 | U24: =(I24-I23)/I23 -> -0.0045240616 | V24: =(J24-J23)/J23 -> -0.0023428212 | ... Y24: =(M24-M23)/M23 -> -0.0016163897
B25: 43119 | C25: 41.754818 | D25: 153.34811 | E25: 172.05026 | F25: 239.14603 | G25: 108.85666 | H25: 36.755325 | I25: 75.744362 | J25: 145.98291 | K25: 5.6890135 | L25: 61.863678 | M25: 2810.3 | O25: =(C25-C24)/C24 -> -0.0044626384 | P25: =(D25-D24)/D24 -> 0.029174701 | Q25: =(E25-E24)/E24 -> 0.0040724849 | R25: =(F25-F24)/F24 -> 0.0078622997 | S25: =(G25-G24)/G24 -> -0.039912373 | T25: =(H25-H24)/H24 -> 0.005972972 | U25: =(I25-I24)/I24 -> -0.0038450632 | V25: =(J25-J24)/J24 -> 0.0088788939 | ... Y25: =(M25-M24)/M24 -> 0.0043852351
... B2054: 46070 | C2054: 258.66 | D2054: 590.23999 | E2054: 1022.0581 | F2054: 376.35999 | G2054: 257.465 | H2054: 79.300003 | I2054: 1064.635 | J2054: 330.92001 | K2054: 179.81 | L2054: 45.48 | M2054: 6836.75 | O2054: =(C2054-C2053)/C2053 -> 0.011259695 | P2054: =(D2054-D2053)/D2053 -> -0.017919867 | Q2054: =(E2054-E2053)/E2053 -> 0.0035132011 | R2054: =(F2054-F2053)/F2053 -> 0.0043765588 | S2054: =(G2054-G2053)/G2053 -> -0.018732405 | T2054: =(H2054-H2053)/H2053 -> 0.0078800552 | U2054: =(I2054-I2053)/I2053 -> 0.023687509 | V2054: =(J2054-J2053)/J2053 -> 0.010196065 | ... Y2054: =(M2054-M2053)/M2053 -> 8.4854258e-05

Sheet Monthly
A2: Monthly | E2: Data fetched using python (yfinance)
O5: Standard Deviation (Monthly)
O6: =STDEV(O14:O110) -> 0.082158082 | P6: =STDEV(P14:P110) -> 0.078109895 | Q6: =STDEV(Q14:Q110) -> 0.061088797 | R6: =STDEV(R14:R110) -> 0.098229052 | S6: =STDEV(S14:S110) -> 0.077759915 | T6: =STDEV(T14:T110) -> 0.051729292 | U6: =STDEV(U14:U110) -> 0.085080085 | V6: =STDEV(V14:V110) -> 0.050849489 | ... Y6: =STDEV(Y14:Y110) -> 0.04715625
B10: Monthly Close price 2018-2026 | O10: Returns m/m
B11: Date | C11: AAPL | D11: CMI | E11: COST | F11: FDX | G11: IBM | H11: KO | I11: LLY | J11: MCD | K11: NVDA | L11: OXY | M11: ^SPX | O11: AAPL | P11: CMI | Q11: COST | R11: FDX | S11: IBM | T11: KO | U11: LLY | V11: MCD | W11: NVDA | X11: OXY | Y11: ^SPX
B13: 43101 | C13: 39.174095 | D13: 152.47218 | E13: 174.35876 | F13: 228.82422 | G13: 109.74837 | H13: 37.090454 | I13: 72.164925 | J13: 141.85507 | K13: 6.0769162 | L13: 61.388741 | M13: 2823.8101
B14: 43132 | C14: 41.675259 | D14: 136.38965 | E14: 170.80658 | F14: 214.81473 | G14: 104.47208 | H14: 33.684586 | I14: 68.239922 | J14: 130.74806 | K14: 5.9829698 | L14: 53.71616 | M14: 2713.8301 | O14: =(C14-C13)/C13 -> 0.063847384 | P14: =(D14-D13)/D13 -> -0.10547848 | Q14: =(E14-E13)/E13 -> -0.020372851 | R14: =(F14-F13)/F13 -> -0.061223812 | S14: =(G14-G13)/G13 -> -0.048076259 | T14: =(H14-H13)/H13 -> -0.091826013 | U14: =(I14-I13)/I13 -> -0.054389346 | V14: =(J14-J13)/J13 -> -0.078298292 | ... Y14: =(M14-M13)/M13 -> -0.038947372
B15: 43160 | C15: 39.416019 | D15: 132.31802 | E15: 169.04776 | F15: 209.32251 | G15: 103.87585 | H15: 33.848255 | I15: 69.060219 | J15: 130.44086 | K15: 5.7291603 | L15: 53.192116 | M15: 2640.8701 | O15: =(C15-C14)/C14 -> -0.054210562 | P15: =(D15-D14)/D14 -> -0.029852887 | Q15: =(E15-E14)/E14 -> -0.010297142 | R15: =(F15-F14)/F14 -> -0.025567232 | S15: =(G15-G14)/G14 -> -0.0057069979 | T15: =(H15-H14)/H14 -> 0.0048588867 | U15: =(I15-I14)/I14 -> 0.012020782 | V15: =(J15-J14)/J14 -> -0.0023495966 | ... Y15: =(M15-M14)/M14 -> -0.026884499
B16: 43191 | C16: 38.824024 | D16: 130.49759 | E16: 176.87975 | F16: 215.95244 | G16: 98.141441 | H16: 33.974068 | I16: 72.362801 | J16: 139.66621 | K16: 5.5636611 | L16: 64.020073 | M16: 2648.05 | O16: =(C16-C15)/C15 -> -0.015019153 | P16: =(D16-D15)/D15 -> -0.013758024 | Q16: =(E16-E15)/E15 -> 0.046330016 | R16: =(F16-F15)/F15 -> 0.031673271 | S16: =(G16-G15)/G15 -> -0.055204486 | T16: =(H16-H15)/H15 -> 0.0037169576 | U16: =(I16-I15)/I15 -> 0.047821768 | V16: =(J16-J15)/J15 -> 0.070724444 | ... Y16: =(M16-M15)/M15 -> 0.002718775
B17: 43221 | C17: 43.900784 | D17: 116.23642 | E17: 177.84872 | F17: 217.62973 | G17: 95.670303 | H17: 33.808968 | I17: 75.906448 | J17: 133.46867 | K17: 6.2387714 | L17: 69.770752 | M17: 2705.27 | O17: =(C17-C16)/C16 -> 0.13076335 | P17: =(D17-D16)/D16 -> -0.10928301 | Q17: =(E17-E16)/E16 -> 0.0054781789 | R17: =(F17-F16)/F16 -> 0.0077669504 | S17: =(G17-G16)/G16 -> -0.025179353 | T17: =(H17-H16)/H16 -> -0.0048595917 | U17: =(I17-I16)/I16 -> 0.048970572 | V17: =(J17-J16)/J16 -> -0.044373941 | ... Y17: =(M17-M16)/M16 -> 0.021608342
B18: 43252 | C18: 43.654991 | D18: 109.37373 | E18: 188.03061 | F18: 198.35826 | G18: 95.630211 | H18: 34.485142 | I18: 76.690468 | J18: 130.69934 | K18: 5.8641467 | L18: 69.33992 | M18: 2718.3701 | O18: =(C18-C17)/C17 -> -0.0055988155 | P18: =(D18-D17)/D17 -> -0.059040822 | Q18: =(E18-E17)/E17 -> 0.057250255 | R18: =(F18-F17)/F17 -> -0.088551638 | S18: =(G18-G17)/G17 -> -0.0004190691 | T18: =(H18-H17)/H17 -> 0.019999847 | U18: =(I18-I17)/I17 -> 0.01032876 | V18: =(J18-J17)/J17 -> -0.020748935 | ... Y18: =(M18-M17)/M17 -> 0.0048424363
B19: 43282 | C19: 44.87661 | D19: 117.44107 | E19: 196.78526 | F19: 215.35794 | G19: 99.210381 | H19: 36.989594 | I19: 88.805649 | J19: 132.24309 | K19: 6.0611858 | L19: 70.171867 | M19: 2816.29 | O19: =(C19-C18)/C18 -> 0.027983482 | P19: =(D19-D18)/D18 -> 0.073759439 | Q19: =(E19-E18)/E18 -> 0.046559728 | R19: =(F19-F18)/F18 -> 0.085701899 | S19: =(G19-G18)/G18 -> 0.037437643 | T19: =(H19-H18)/H18 -> 0.072624082 | U19: =(I19-I18)/I18 -> 0.15797506 | V19: =(J19-J18)/J18 -> 0.011811436 | ... Y19: =(M19-M18)/M18 -> 0.036021556
B20: 43313 | C20: 53.682617 | D20: 116.61048 | E20: 209.75974 | F20: 213.67622 | G20: 100.2714 | H20: 35.355473 | I20: 94.953125 | J20: 136.18002 | K20: 6.9478621 | L20: 66.777397 | M20: 2901.52 | O20: =(C20-C19)/C19 -> 0.19622711 | P20: =(D20-D19)/D19 -> -0.0070723921 | Q20: =(E20-E19)/E19 -> 0.065932133 | R20: =(F20-F19)/F19 -> -0.0078089385 | S20: =(G20-G19)/G19 -> 0.010694646 | T20: =(H20-H19)/H19 -> -0.044177856 | U20: =(I20-I19)/I19 -> 0.069223932 | V20: =(J20-J19)/J19 -> 0.029770444 | ... Y20: =(M20-M19)/M19 -> 0.030263211
B21: 43344 | C21: 53.423592 | D21: 121.07131 | E21: 211.85892 | F21: 210.90837 | G21: 104.62755 | H21: 36.640553 | I21: 96.978012 | J21: 141.30414 | K21: 6.9600825 | L21: 68.70034 | M21: 2913.98 | O21: =(C21-C20)/C20 -> -0.0048251294 | P21: =(D21-D20)/D20 -> 0.038254114 | Q21: =(E21-E20)/E20 -> 0.010007555 | R21: =(F21-F20)/F20 -> -0.01295349 | S21: =(G21-G20)/G20 -> 0.043443572 | T21: =(H21-H20)/H20 -> 0.036347413 | U21: =(I21-I20)/I20 -> 0.021325123 | V21: =(J21-J20)/J20 -> 0.037627509 | ... Y21: =(M21-M20)/M20 -> 0.0042942874
B22: 43374 | C22: 51.795368 | D22: 113.29658 | E22: 206.22147 | F22: 193.50705 | G22: 79.870102 | H22: 38.304222 | I22: 97.999237 | J22: 149.42139 | K22: 5.2216725 | L22: 56.645195 | M22: 2711.74 | O22: =(C22-C21)/C21 -> -0.030477611 | P22: =(D22-D21)/D21 -> -0.064216158 | Q22: =(E22-E21)/E21 -> -0.026609459 | R22: =(F22-F21)/F21 -> -0.082506547 | S22: =(G22-G21)/G21 -> -0.23662455 | T22: =(H22-H21)/H21 -> 0.045405145 | U22: =(I22-I21)/I21 -> 0.01053048 | V22: =(J22-J21)/J21 -> 0.057445229 | ... Y22: =(M22-M21)/M21 -> -0.069403356
B23: 43405 | C23: 42.262707 | D23: 125.20728 | E23: 208.61172 | F23: 201.11241 | G23: 85.986832 | H23: 40.320251 | I23: 107.21715 | J23: 159.22792 | K23: 4.0477071 | L23: 59.347809 | M23: 2760.1699 | O23: =(C23-C22)/C22 -> -0.18404467 | P23: =(D23-D22)/D22 -> 0.10512856 | Q23: =(E23-E22)/E22 -> 0.011590737 | R23: =(F23-F22)/F22 -> 0.039302764 | S23: =(G23-G22)/G22 -> 0.076583472 | T23: =(H23-H22)/H22 -> 0.05263204 | U23: =(I23-I22)/I22 -> 0.094061046 | V23: =(J23-J22)/J22 -> 0.065630055 | ... Y23: =(M23-M22)/M22 -> 0.017859357
B24: 43435 | C24: 37.460979 | D24: 111.6494 | E24: 184.18066 | F24: 141.68327 | G24: 79.654037 | H24: 38.179764 | I24: 105.10482 | J24: 150.91231 | K24: 3.3097322 | L24: 51.839607 | M24: 2506.8501 | O24: =(C24-C23)/C23 -> -0.11361618 | P24: =(D24-D23)/D23 -> -0.10828351 | Q24: =(E24-E23)/E23 -> -0.1171126 | R24: =(F24-F23)/F23 -> -0.29550209 | S24: =(G24-G23)/G23 -> -0.073648419 | T24: =(H24-H23)/H23 -> -0.053087161 | U24: =(I24-I23)/I23 -> -0.019701397 | V24: =(J24-J23)/J23 -> -0.05222459 | ... Y24: =(M24-M23)/M23 -> -0.091776895
B25: 43466 | C25: 39.527103 | D25: 122.9029 | E25: 194.05382 | F25: 156.41837 | G25: 94.194565 | H25: 38.808712 | I25: 108.86502 | J25: 151.94064 | K25: 3.5638497 | L25: 57.059433 | M25: 2704.1001 | O25: =(C25-C24)/C24 -> 0.055154029 | P25: =(D25-D24)/D24 -> 0.10079322 | Q25: =(E25-E24)/E24 -> 0.05360581 | R25: =(F25-F24)/F24 -> 0.10400022 | S25: =(G25-G24)/G24 -> 0.18254602 | T25: =(H25-H24)/H24 -> 0.01647334 | U25: =(I25-I24)/I24 -> 0.035775719 | V25: =(J25-J24)/J24 -> 0.0068141266 | ... Y25: =(M25-M24)/M24 -> 0.078684402
... B110: 46054 | C110: 258.62 | D110: 590.23999 | E110: 1022.0581 | F110: 376.35999 | G110: 257.60999 | H110: 79.305 | I110: 1064.635 | J110: 330.92001 | K110: 179.92999 | L110: 45.48 | M110: 6836.75 | O110: =(C110-C109)/C109 -> -0.0023817226 | P110: =(D110-D109)/D109 -> 0.019729765 | Q110: =(E110-E109)/E109 -> 0.08849178 | R110: =(F110-F109)/F109 -> 0.16791307 | S110: =(G110-G109)/G109 -> -0.15526984 | T110: =(H110-H109)/H109 -> 0.060085589 | U110: =(I110-I109)/I109 -> 0.028213751 | V110: =(J110-J109)/J109 -> 0.050539725 | ... Y110: =(M110-M109)/M109 -> -0.014739782
