Workbook

Sheet Data Daily
A1: Début | B1: 43831
A2: Fin
A3: ROI | B3: 5.2505052 | C3: 0.93503072 | D3: 9.1724679 | E3: 14.21356 | F3: 6.8505481 | G3: 2.1957615 | H3: 14.805947 | I3: 5.8134306 | J3: 7.4301633 | K3: 3.8440551 | L3: 7.8274275 | M3: 10.718121 | N3: 4.855415 | O3: 5.5379046 | P3: 5.4611829 | Q3: 9.1927588 | R3: 7.1387091 | S3: 6.6104918 | T3: 1.2844051 | U3: 11.598615 | V3: -0.30825678 | W3: 9.282531 | X3: 9.9304404 | Y3: 6.8273297 | Z3: 3.6892833 | AA3: 13.518798 | AB3: 7.0163417 | AC3: 11.350183 | AD3: 5.1808401 | AE3: 22.018988 | AF3: 1.2727701 | AG3: 13.641934 | AH3: 4.7665285 | AI3: 7.7627652 | AJ3: -17.137947 | AK3: 1.76546 | AL3: 11.523608 | AM3: 8.619193 | AN3: 5.0216166 | AO3: 5.3558281
A4: WACC en % | B4: 14.367405 | C4: 12.185419 | D4: 10.88195 | E4: 13.343262 | F4: 8.4010396 | G4: 14.032748 | H4: 11.979887 | I4: 9.2732576 | J4: 13.385847 | K4: 11.849612 | L4: 12.481588 | M4: 11.272379 | N4: 13.082016 | O4: 11.632988 | P4: 9.0330867 | Q4: 10.387129 | R4: 13.072406 | S4: 12.670382 | T4: 14.861122 | U4: 11.679322 | V4: 15.848917 | W4: 12.803966 | X4: 14.371309 | Y4: 11.724103 | Z4: 18.343572 | AA4: 10.631104 | AB4: 6.4847822 | AC4: 11.489865 | AD4: 12.485264 | AE4: 14.568076 | AF4: 13.32931 | AG4: 13.935409 | AH4: 9.9015457 | AI4: 15.781893 | AJ4: 17.823856 | AK4: 6.6922265 | AL4: 16.789632 | AM4: 7.7187638 | AN4: 12.276331 | AO4: 11.569979 | AZ4: DEVISES
B5: ACCOR SA | C5: CREDIT AGRICOLE SA | D5: AIR LIQUIDE SA | E5: AIRBUS SE | F5: DANONE | G5: BNP PARIBAS | H5: BUREAU VERITAS SA | I5: CARREFOUR SA | J5: CAPGEMINI SE | K5: AXA SA | L5: VINCI SA | M5: DASSAULT SYSTEMES SE | N5: ESSILORLUXOTTICA | O5: BOUYGUES SA | P5: ENGIE | Q5: EURONEXT NV | R5: EUROFINS SCIENTIFIC | S5: EIFFAGE | T5: SOCIETE GENERALE SA | U5: THALES SA | V5: KERING | W5: LEGRAND SA | X5: LVMH MOET HENNESSY LOUIS VUI | Y5: MICHELIN (CGDE) | Z5: ARCELORMITTAL | AA5: L'OREAL | AB5: ORANGE | AC5: PUBLICIS GROUPE | AD5: PERNOD RICARD SA | AE5: HERMES INTERNATIONAL | AF5: RENAULT SA | AG5: SAFRAN SA | AH5: SANOFI | AI5: COMPAGNIE DE SAINT GOBAIN | AJ5: STELLANTIS NV | AK5: STMICROELECTRONICS NV | AL5: SCHNEIDER ELECTRIC SE | AM5: TOTALENERGIES SE | AN5: UNIBAIL-RODAMCO-WESTFIELD | AO5: VEOLIA ENVIRONNEMENT | AP5: CAC 40 INDEX | AR5: EUR-USD X-RATE | AS5: EUR-GBP X-RATE | AT5: EUR-JPY X-RATE | AW5: BRENT CRUDE FUTR Nov26
B6: AC FP | C6: ACA FP | D6: AI FP | E6: AIR FP | F6: BN FP | G6: BNP FP | H6: BVI FP | I6: CA FP | J6: CAP FP | K6: CS FP | L6: DG FP | M6: DSY FP | N6: EL FP | O6: EN FP | P6: ENGI FP | Q6: ENX FP | R6: ERF FP | S6: FGR FP | T6: GLE FP | U6: HO FP | V6: KER FP | W6: LR FP | X6: MC FP | Y6: ML FP | Z6: MT NA | AA6: OR FP | AB6: ORA FP | AC6: PUB FP | AD6: RI FP | AE6: RMS FP | AF6: RNO FP | AG6: SAF FP | AH6: SAN FP | AI6: SGO FP | AJ6: STLAP FP | AK6: STMPA FP | AL6: SU FP | AM6: TTE FP | AN6: URW FP | AO6: VIE FP | AP6: CAC Index | AR6: EURUSD Curncy | AS6: EURGBP Curncy | AT6: EURJPY Curncy | AW6: COA Comdty | AZ6: Date de début | BA6: 43831
B7: AC FP Equity | C7: ACA FP Equity | D7: AI FP Equity | E7: AIR FP Equity | F7: BN FP Equity | G7: BNP FP Equity | H7: BVI FP Equity | I7: CA FP Equity | J7: CAP FP Equity | K7: CS FP Equity | L7: DG FP Equity | M7: DSY FP Equity | N7: EL FP Equity | O7: EN FP Equity | P7: ENGI FP Equity | Q7: ENX FP Equity | R7: ERF FP Equity | S7: FGR FP Equity | T7: GLE FP Equity | U7: HO FP Equity | V7: KER FP Equity | W7: LR FP Equity | X7: MC FP Equity | Y7: ML FP Equity | Z7: MT NA Equity | AA7: OR FP Equity | AB7: ORA FP Equity | AC7: PUB FP Equity | AD7: RI FP Equity | AE7: RMS FP Equity | AF7: RNO FP Equity | AG7: SAF FP Equity | AH7: SAN FP Equity | AI7: SGO FP Equity | AJ7: STLAP FP Equity | AK7: STMPA FP Equity | AL7: SU FP Equity | AM7: TTE FP Equity | AN7: URW FP Equity | AO7: VIE FP Equity | AP7: CAC Index | AR7: EURUSD Curncy | AS7: EURGBP Curncy | AT7: EURJPY Curncy | AW7: COA Comdty | AZ7: Date de fin
A8: 43831 | B8: 41.75 | C8: 12.925 | D8: 94.8159 | E8: 130.48 | F8: 73.9 | G8: 52.83 | H8: 23.26 | I8: 14.95 | J8: 108.9 | K8: 25.11 | L8: 99 | M8: 29.31 | N8: 135.8 | O8: 37.88 | P8: 14.4 | Q8: 66.324 | R8: 49.42 | S8: 102 | T8: 31.015 | U8: 92.52 | V8: 585.2 | W8: 72.64 | X8: 414.2 | Y8: 27.275 | Z8: 15.642 | AA8: 264 | AB8: 13.12 | AC8: 40.36 | AD8: 159.4 | AE8: 666.2 | AF8: 42.18 | AG8: 137.65 | AH8: 89.1343 | AI8: 36.5 | AJ8: #N/A N/A | AK8: 23.97 | AL8: 91.5 | AM8: 49.2 | AN8: 140.65 | AO8: 22.8605 | AP8: 5978.06 | AR8: 1.1212 | AS8: 0.84624 | AT8: 121.92 | AW8: 58.53 | BA8: EUR-USD X-RATE | BB8: EUR-GBP X-RATE | BC8: EUR-JPY X-RATE
A9: 43832 | B9: 41.76 | C9: 13.185 | D9: 95.1916 | E9: 133.52 | F9: 73.98 | G9: 53.58 | H9: 23.63 | I9: 14.97 | J9: 111.05 | K9: 25.46 | L9: 99.84 | M9: 29.46 | N9: 136.7 | O9: 38.61 | P9: 14.695 | Q9: 67.876 | R9: 50.5 | S9: 103.25 | T9: 31.655 | U9: 92.94 | V9: 598 | W9: 73.54 | X9: 419.15 | Y9: 27.1125 | Z9: 15.83 | AA9: 264.2 | AB9: 13.175 | AC9: 40.68 | AD9: 160.35 | AE9: 671 | AF9: 41.9 | AG9: 137.6 | AH9: 89.731 | AI9: 36.985 | AJ9: #N/A N/A | AK9: 24.79 | AL9: 93.06 | AM9: 49.815 | AN9: 141.4 | AO9: 23.0726 | AP9: 6041.5 | AR9: 1.1172 | AS9: 0.84994 | AT9: 121.32 | AW9: 58.95 | BA9: EURUSD Curncy | BB9: EURGBP Curncy | BC9: EURJPY Curncy
A10: 43833 | B10: 41.21 | C10: 13.105 | D10: 94.8911 | E10: 134.04 | F10: 74.62 | G10: 52.94 | H10: 23.59 | I10: 15.03 | J10: 111.15 | K10: 25.47 | L10: 99.22 | M10: 29.69 | N10: 136.25 | O10: 38.13 | P10: 14.69 | Q10: 67.739 | R10: 50.15 | S10: 102.65 | T10: 31.335 | U10: 94.12 | V10: 600.9 | W10: 73.4 | X10: 419.1 | Y10: 26.95 | Z10: 15.26 | AA10: 263.9 | AB10: 13.26 | AC10: 40.78 | AD10: 161.2 | AE10: 675.4 | AF10: 41.22 | AG10: 138 | AH10: 90.288 | AI10: 36.34 | AJ10: #N/A N/A | AK10: 24.58 | AL10: 92.82 | AM10: 50.38 | AN10: 141.6 | AO10: 23.1883 | AP10: 6044.16 | AR10: 1.1161 | AS10: 0.85335 | AT10: 120.49 | AW10: 58.53
A11: 43836 | B11: 40.25 | C11: 12.975 | D11: 94.2524 | E11: 133.46 | F11: 74.76 | G11: 52.68 | H11: 23.45 | I11: 15.03 | J11: 109.3 | K11: 25.135 | L11: 98.72 | M11: 29.5 | N11: 136.1 | O11: 37.54 | P11: 14.705 | Q11: 67.83 | R11: 49.46 | S11: 101.6 | T11: 31.08 | U11: 95.04 | V11: 590.8 | W11: 73.34 | X11: 415.15 | Y11: 26.9375 | Z11: 15.006 | AA11: 263 | AB11: 13.19 | AC11: 41.1 | AD11: 161.2 | AE11: 669.8 | AF11: 41.35 | AG11: 136.45 | AH11: 90.8549 | AI11: 36 | AJ11: #N/A N/A | AK11: 24.03 | AL11: 92.7 | AM11: 50.44 | AN11: 138.7 | AO11: 23.0533 | AP11: 6013.59 | AR11: 1.1197 | AS11: 0.85023 | AT11: 121.33 | AW11: 58.5 | AZ11: Dates | BA11: LAST_price | BB11: LAST_price | BC11: LAST_price
A12: 43837 | B12: 40.35 | C12: 12.945 | D12: 93.8392 | E12: 132 | F12: 74.06 | G12: 52.66 | H12: 23.4 | I12: 15.15 | J12: 109.35 | K12: 25.29 | L12: 98.04 | M12: 29.74 | N12: 137.05 | O12: 37.99 | P12: 14.89 | Q12: 67.967 | R12: 49.56 | S12: 102.2 | T12: 31.46 | U12: 94.8 | V12: 596.3 | W12: 72.96 | X12: 416 | Y12: 27.0125 | Z12: 15.062 | AA12: 259.6 | AB12: 13.2 | AC12: 42.26 | AD12: 160.55 | AE12: 678.2 | AF12: 42.81 | AG12: 137.7 | AH12: 90.5366 | AI12: 35.855 | AJ12: #N/A N/A | AK12: 24.63 | AL12: 92.32 | AM12: 50.11 | AN12: 139.4 | AO12: 22.8509 | AP12: 6012.35 | AR12: 1.1153 | AS12: 0.84984 | AT12: 120.92 | AW12: 58.89 | AZ12: 43831 | BA12: 1.1212 | BB12: 0.84624 | BC12: 121.92
A13: 43838 | B13: 40.4 | C13: 13.005 | D13: 93.9144 | E13: 134.38 | F13: 72.56 | G13: 52.78 | H13: 23.53 | I13: 15.17 | J13: 109.05 | K13: 25.28 | L13: 99.92 | M13: 30.1 | N13: 138.9 | O13: 37.97 | P13: 14.87 | Q13: 68.925 | R13: 48.94 | S13: 103.8 | T13: 31.77 | U13: 96.18 | V13: 597.3 | W13: 72.84 | X13: 418.8 | Y13: 27.5625 | Z13: 15.24 | AA13: 261.2 | AB13: 13.11 | AC13: 42.19 | AD13: 159.45 | AE13: 684.2 | AF13: 42.635 | AG13: 137.5 | AH13: 90.8449 | AI13: 35.9 | AJ13: #N/A N/A | AK13: 24.6 | AL13: 92.56 | AM13: 50.24 | AN13: 135.7 | AO13: 22.7352 | AP13: 6031 | AR13: 1.1105 | AS13: 0.84803 | AT13: 121.18 | AW13: 58.34 | AZ13: 43832 | BA13: 1.1172 | BB13: 0.84994 | BC13: 121.32
A14: 43839 | B14: 40.58 | C14: 13.015 | D14: 94.29 | E14: 134.92 | F14: 72.7 | G14: 52.4 | H14: 23.63 | I14: 15.185 | J14: 109.05 | K14: 25.25 | L14: 98.92 | M14: 30.49 | N14: 141.15 | O14: 37.97 | P14: 14.81 | Q14: 69.93 | R14: 48.76 | S14: 103.4 | T14: 31.785 | U14: 96.5 | V14: 595.9 | W14: 72.82 | X14: 424.5 | Y14: 27.6875 | Z14: 15.2 | AA14: 262.8 | AB14: 13.15 | AC14: 42.02 | AD14: 159.7 | AE14: 687 | AF14: 42.075 | AG14: 139.45 | AH14: 91.5014 | AI14: 35.69 | AJ14: #N/A N/A | AK14: 25.2 | AL14: 91.8 | AM14: 49.96 | AN14: 133.75 | AO14: 22.9087 | AP14: 6042.55 | AR14: 1.1106 | AS14: 0.84994 | AT14: 121.63 | AW14: 58.54 | AZ14: 43833 | BA14: 1.1161 | BB14: 0.85335 | BC14: 120.49
A15: 43840 | B15: 40.48 | C15: 12.875 | D15: 94.5154 | E15: 134.42 | F15: 72.6 | G15: 52.16 | H15: 23.44 | I15: 15.015 | J15: 110.25 | K15: 25.355 | L15: 99.42 | M15: 30.8 | N15: 141 | O15: 37.63 | P15: 14.755 | Q15: 70.34 | R15: 48.9 | S15: 104.6 | T15: 31.435 | U15: 95.92 | V15: 592.1 | W15: 72.42 | X15: 423.65 | Y15: 27.7375 | Z15: 14.92 | AA15: 263.9 | AB15: 13.12 | AC15: 41.92 | AD15: 158.9 | AE15: 689 | AF15: 41.84 | AG15: 138.5 | AH15: 92.2175 | AI15: 35.22 | AJ15: #N/A N/A | AK15: 24.73 | AL15: 92.14 | AM15: 49.785 | AN15: 131.75 | AO15: 23.4776 | AP15: 6037.11 | AR15: 1.1121 | AS15: 0.85115 | AT15: 121.65 | AW15: 58.17 | AZ15: 43836 | BA15: 1.1197 | BB15: 0.85023 | BC15: 121.33
A16: 43843 | B16: 40.34 | C16: 12.855 | D16: 94.8535 | E16: 135.12 | F16: 72.26 | G16: 51.93 | H16: 24.32 | I16: 15.05 | J16: 111.9 | K16: 25.335 | L16: 99.74 | M16: 30.9 | N16: 138.8 | O16: 37.89 | P16: 14.8 | Q16: 70.34 | R16: 49.12 | S16: 103.7 | T16: 31.435 | U16: 96.78 | V16: 593.8 | W16: 72.04 | X16: 426.75 | Y16: 27.7 | Z16: 15.224 | AA16: 262.5 | AB16: 13.055 | AC16: 43.08 | AD16: 162.8 | AE16: 689.6 | AF16: 40.66 | AG16: 137.45 | AH16: 91.571 | AI16: 35.67 | AJ16: #N/A N/A | AK16: 24.95 | AL16: 91.86 | AM16: 49.56 | AN16: 132 | AO16: 23.5065 | AP16: 6036.14 | AR16: 1.1134 | AS16: 0.85723 | AT16: 122.42 | AW16: 58.1 | AZ16: 43837 | BA16: 1.1153 | BB16: 0.84984 | BC16: 120.92
A17: 43844 | B17: 41.01 | C17: 12.92 | D17: 95.417 | E17: 135.1 | F17: 71.4 | G17: 52.17 | H17: 24.46 | I17: 15.1 | J17: 114.25 | K17: 24.685 | L17: 100.4 | M17: 30.8 | N17: 139.85 | O17: 38.36 | P17: 14.81 | Q17: 70.34 | R17: 49 | S17: 103.6 | T17: 31.435 | U17: 96.46 | V17: 592.1 | W17: 72.82 | X17: 431 | Y17: 27.725 | Z17: 15.134 | AA17: 263.8 | AB17: 13.04 | AC17: 43.4 | AD17: 165.7 | AE17: 699.6 | AF17: 40.5 | AG17: 137.6 | AH17: 90.7753 | AI17: 35.945 | AJ17: #N/A N/A | AK17: 25.07 | AL17: 92.62 | AM17: 49.16 | AN17: 133.4 | AO17: 23.8922 | AP17: 6040.89 | AR17: 1.1128 | AS17: 0.85476 | AT17: 122.4 | AW17: 58.23 | AZ17: 43838 | BA17: 1.1105 | BB17: 0.84803 | BC17: 121.18
A18: 43845 | B18: 40.58 | C18: 12.765 | D18: 95.2667 | E18: 134.26 | F18: 72.44 | G18: 50.96 | H18: 24.72 | I18: 15.025 | J18: 114.9 | K18: 24.18 | L18: 100.55 | M18: 31.21 | N18: 142.1 | O18: 38.17 | P18: 14.9 | Q18: 70.249 | R18: 49.58 | S18: 104.2 | T18: 30.95 | U18: 96.32 | V18: 594.6 | W18: 72.56 | X18: 431.45 | Y18: 27.075 | Z18: 14.676 | AA18: 269.4 | AB18: 13.03 | AC18: 43.04 | AD18: 167.25 | AE18: 708.6 | AF18: 40 | AG18: 139.25 | AH18: 91.2229 | AI18: 35.425 | AJ18: #N/A N/A | AK18: 24.62 | AL18: 92.34 | AM18: 48.58 | AN18: 133.85 | AO18: 24.2393 | AP18: 6032.61 | AR18: 1.115 | AS18: 0.85519 | AT18: 122.55 | AW18: 58.1 | AZ18: 43839 | BA18: 1.1106 | BB18: 0.84994 | BC18: 121.63
A19: 43846 | B19: 40.26 | C19: 12.775 | D19: 95.6799 | E19: 133.4 | F19: 73.5 | G19: 50.59 | H19: 24.79 | I19: 14.835 | J19: 114.8 | K19: 24.2 | L19: 100.45 | M19: 31.04 | N19: 142.1 | O19: 37.8 | P19: 14.98 | Q19: 70.843 | R19: 48.62 | S19: 104.45 | T19: 30.61 | U19: 97.3 | V19: 605.1 | W19: 72.38 | X19: 431.9 | Y19: 26.9625 | Z19: 14.65 | AA19: 269.8 | AB19: 12.855 | AC19: 42.94 | AD19: 167.5 | AE19: 712 | AF19: 39.535 | AG19: 141 | AH19: 91.1135 | AI19: 35.07 | AJ19: #N/A N/A | AK19: 24.79 | AL19: 92.62 | AM19: 48.79 | AN19: 135.05 | AO19: 24.461 | AP19: 6039.03 | AR19: 1.1137 | AS19: 0.85155 | AT19: 122.68 | AW19: 58.24 | AZ19: 43840 | BA19: 1.1121 | BB19: 0.85115 | BC19: 121.65
A20: 43847 | B20: 40.2 | C20: 12.87 | D20: 97.2201 | E20: 136.78 | F20: 73.7 | G20: 50.75 | H20: 25.2 | I20: 14.75 | J20: 116.4 | K20: 24.375 | L20: 102.4 | M20: 31.51 | N20: 144.7 | O20: 37.91 | P20: 15.195 | Q20: 71.208 | R20: 47.96 | S20: 104.55 | T20: 30.65 | U20: 98.78 | V20: 610.2 | W20: 73.8 | X20: 439.05 | Y20: 27.5 | Z20: 14.64 | AA20: 275.3 | AB20: 13.03 | AC20: 41.78 | AD20: 170.6 | AE20: 725.6 | AF20: 39.26 | AG20: 142.55 | AH20: 91.6903 | AI20: 35.365 | AJ20: #N/A N/A | AK20: 25.16 | AL20: 94.22 | AM20: 48.505 | AN20: 134.1 | AO20: 24.731 | AP20: 6100.72 | AR20: 1.1092 | AS20: 0.85201 | AT20: 122.19 | AW20: 58.22 | AZ20: 43843 | BA20: 1.1134 | BB20: 0.85723 | BC20: 122.42
A21: 43850 | B21: 39.38 | C21: 12.81 | D21: 96.8069 | E21: 137.9 | F21: 73.22 | G21: 50.49 | H21: 25.05 | I21: 14.75 | J21: 117 | K21: 24.475 | L21: 102.1 | M21: 31.57 | N21: 142.9 | O21: 38.51 | P21: 15.3 | Q21: 70.706 | R21: 48.3 | S21: 105.15 | T21: 30.585 | U21: 99.9 | V21: 599 | W21: 73.26 | X21: 429.75 | Y21: 27.8875 | Z21: 14.6 | AA21: 274.3 | AB21: 13.06 | AC21: 42.23 | AD21: 169.15 | AE21: 717 | AF21: 39.595 | AG21: 142.15 | AH21: 91.4019 | AI21: 35.13 | AJ21: #N/A N/A | AK21: 25.36 | AL21: 93.98 | AM21: 48.57 | AN21: 132 | AO21: 24.972 | AP21: 6078.54 | AR21: 1.1095 | AS21: 0.85284 | AT21: 122.25 | AW21: 58.25 | AZ21: 43844 | BA21: 1.1128 | BB21: 0.85476 | BC21: 122.4
A22: 43851 | B22: 38.84 | C22: 12.765 | D22: 97.4455 | E22: 136.4 | F22: 73.3 | G22: 50.21 | H22: 25.01 | I22: 14.755 | J22: 117.55 | K22: 24.55 | L22: 102.2 | M22: 31.68 | N22: 142.85 | O22: 38.43 | P22: 15.285 | Q22: 71.345 | R22: 47.82 | S22: 105.35 | T22: 30.425 | U22: 99.02 | V22: 586.6 | W22: 72.18 | X22: 424.95 | Y22: 27.8125 | Z22: 14.216 | AA22: 270.7 | AB22: 13.1 | AC22: 42.08 | AD22: 168.6 | AE22: 709.2 | AF22: 39.285 | AG22: 142 | AH22: 90.8648 | AI22: 35.095 | AJ22: #N/A N/A | AK22: 25.09 | AL22: 93.6 | AM22: 48.115 | AN22: 132.35 | AO22: 25.1649 | AP22: 6045.99 | AR22: 1.1082 | AS22: 0.84938 | AT22: 121.77 | AW22: 58.51 | AZ22: 43845 | BA22: 1.115 | BB22: 0.85519 | BC22: 122.55
A23: 43852 | B23: 38.59 | C23: 12.63 | D23: 97.3328 | E23: 137.98 | F23: 72.9 | G23: 50.08 | H23: 25.24 | I23: 14.455 | J23: 117.7 | K23: 24.39 | L23: 100.9 | M23: 32.1 | N23: 140.25 | O23: 38.23 | P23: 15.295 | Q23: 72.075 | R23: 47.88 | S23: 104.3 | T23: 30.32 | U23: 98.32 | V23: 592.2 | W23: 71.88 | X23: 423.45 | Y23: 27.3625 | Z23: 14.252 | AA23: 269 | AB23: 13.13 | AC23: 41.52 | AD23: 167.4 | AE23: 711.2 | AF23: 38.955 | AG23: 140.25 | AH23: 88.3883 | AI23: 35 | AJ23: #N/A N/A | AK23: 25.36 | AL23: 92.98 | AM23: 47.8 | AN23: 130.7 | AO23: 25.4059 | AP23: 6010.98 | AR23: 1.1093 | AS23: 0.84414 | AT23: 121.83 | AW23: 58.09 | AZ23: 43846 | BA23: 1.1137 | BB23: 0.85155 | BC23: 122.68
... A280: 44211 | B280: 30.13 | C280: 10.175 | D280: 99.4741 | E280: 92.55 | F280: 53.62 | G280: 44.435 | H280: 22.89 | I280: 16.61 | J280: 124.15 | K280: 19.916 | L280: 84.72 | M280: 32.55 | N280: 124.05 | O280: 34.52 | P280: 13.615 | Q280: 84.491 | R280: 74.75 | S280: 80.1 | T280: 17.334 | U280: 76.44 | V280: 561.8 | W280: 80 | X280: 493.95 | Y280: 27.2125 | Z280: 19.708 | AA280: 298.4 | AB280: 9.75 | AC280: 44.27 | AD280: 155.55 | AE280: 881 | AF280: 34.07 | AG280: 114.75 | AH280: 81.0881 | AI280: 43.12 | AJ280: #N/A N/A | AK280: 32.93 | AL280: 124.35 | AM280: 37.095 | AN280: 62.5 | AO280: 22.3013 | AP280: 5611.69 | AR280: 1.2082 | AS280: 0.88899 | AT280: 125.56 | AW280: 50.5 | AZ280: 44207 | BA280: 1.2151 | BB280: 0.89904 | BC280: 126.69
A281: 44214 | B281: 29.81 | C281: 10.28 | D281: 99.8497 | E281: 91.19 | F281: 54.72 | G281: 44.805 | H281: 22.78 | I281: 15.46 | J281: 124.85 | K281: 19.734 | L281: 84.66 | M281: 32.08 | N281: 125.05 | O281: 35.27 | P281: 13.485 | Q281: 85.312 | R281: 76.8 | S281: 80.36 | T281: 17.4 | U281: 75.46 | V281: 565.5 | W281: 79.8 | X281: 499.65 | Y281: 27.2375 | Z281: 20.185 | AA281: 296.9 | AB281: 9.67 | AC281: 45.08 | AD281: 155.35 | AE281: 887.6 | AF281: 34.63 | AG281: 113.7 | AH281: 81.1876 | AI281: 42.65 | AJ281: 12.7505 | AK281: 33.07 | AL281: 122.75 | AM281: 36.98 | AN281: 60.46 | AO281: 21.906 | AP281: 5617.27 | AR281: 1.2077 | AS281: 0.88892 | AT281: 125.24 | AW281: 50.22 | AZ281: 44208 | BA281: 1.2207 | BB281: 0.89334 | BC281: 126.66
A282: 44215 | B282: 30.37 | C282: 10.05 | D282: 99.4365 | E282: 91.3 | F282: 56.18 | G282: 44.11 | H282: 22.76 | I282: 15 | J282: 125.4 | K282: 19.65 | L282: 84.84 | M282: 32.12 | N282: 123.1 | O282: 35.09 | P282: 13.58 | Q282: 84.902 | R282: 77.41 | S282: 80.68 | T282: 16.984 | U282: 75.6 | V282: 547.9 | W282: 79.66 | X282: 491.05 | Y282: 26.9 | Z282: 19.204 | AA282: 297.1 | AB282: 9.662 | AC282: 43.01 | AD282: 156.3 | AE282: 862.4 | AF282: 34.18 | AG282: 113.25 | AH282: 82.7789 | AI282: 42.71 | AJ282: 13.147 | AK282: 32.76 | AL282: 122.65 | AM282: 37.15 | AN282: 60.38 | AO282: 22.3206 | AP282: 5598.61 | AR282: 1.2129 | AS282: 0.88984 | AT282: 126.02 | AW282: 50.52 | AZ282: 44209 | BA282: 1.2157 | BB282: 0.89147 | BC282: 126.3
A283: 44216 | B283: 30.16 | C283: 10.205 | D283: 98.4222 | E283: 92.41 | F283: 55.28 | G283: 44.42 | H283: 22.77 | I283: 14.915 | J283: 124.5 | K283: 19.716 | L283: 83.58 | M283: 32.45 | N283: 124.5 | O283: 35.08 | P283: 13.445 | Q283: 83.989 | R283: 77.97 | S283: 80.42 | T283: 17.084 | U283: 78.5 | V283: 556.7 | W283: 79.82 | X283: 507.7 | Y283: 27.75 | Z283: 19.242 | AA283: 293.6 | AB283: 9.662 | AC283: 43.54 | AD283: 154.15 | AE283: 868.2 | AF283: 34.815 | AG283: 114.9 | AH283: 81.9037 | AI283: 43.25 | AJ283: 13.1887 | AK283: 33.5 | AL283: 123.2 | AM283: 37.345 | AN283: 60.58 | AO283: 22.5423 | AP283: 5628.44 | AR283: 1.2106 | AS283: 0.88656 | AT283: 125.35 | AW283: 50.31 | AZ283: 44210 | BA283: 1.2155 | BB283: 0.88794 | BC283: 126.17
A284: 44217 | B284: 31.05 | C284: 10.06 | D284: 98.5349 | E284: 89.36 | F284: 55.08 | G284: 44.34 | H284: 22.53 | I284: 15.075 | J284: 124.3 | K284: 19.518 | L284: 81.52 | M284: 32.85 | N284: 122.6 | O284: 34.5 | P284: 13.315 | Q284: 83.989 | R284: 78.28 | S284: 77.86 | T284: 16.898 | U284: 76.58 | V284: 550.2 | W284: 80.28 | X284: 507.6 | Y284: 28.0625 | Z284: 19.03 | AA284: 294.6 | AB284: 9.562 | AC284: 43.4 | AD284: 153.65 | AE284: 875.6 | AF284: 35.25 | AG284: 111.95 | AH284: 80.9787 | AI284: 43.32 | AJ284: 12.9326 | AK284: 33.4 | AL284: 125.15 | AM284: 36.475 | AN284: 55.5 | AO284: 21.9831 | AP284: 5590.79 | AR284: 1.2164 | AS284: 0.88594 | AT284: 125.93 | AW284: 50.25 | AZ284: 44211 | BA284: 1.2082 | BB284: 0.88899 | BC284: 125.56
A285: 44218 | B285: 29.57 | C285: 9.922 | D285: 99.2111 | E285: 88.83 | F285: 54.56 | G285: 43.085 | H285: 22.27 | I285: 14.715 | J285: 123.4 | K285: 19.212 | L285: 80.46 | M285: 33 | N285: 122.5 | O285: 34.09 | P285: 13.115 | Q285: 83.304 | R285: 78 | S285: 76.5 | T285: 16.34 | U285: 75.5 | V285: 544 | W285: 79.84 | X285: 511.5 | Y285: 27.8625 | Z285: 18.642 | AA285: 296.3 | AB285: 9.588 | AC285: 43.18 | AD285: 153.1 | AE285: 875.6 | AF285: 34.42 | AG285: 110.55 | AH285: 81.0185 | AI285: 42.6 | AJ285: 12.5209 | AK285: 32.6 | AL285: 125.35 | AM285: 36.22 | AN285: 56.94 | AO285: 21.5492 | AP285: 5559.57 | AR285: 1.2171 | AS285: 0.88982 | AT285: 126.33 | AW285: 49.94 | AZ285: 44214 | BA285: 1.2077 | BB285: 0.88892 | BC285: 125.24
A286: 44221 | B286: 28.06 | C286: 9.5 | D286: 98.7228 | E286: 84.87 | F286: 54.7 | G286: 41.23 | H286: 21.93 | I286: 14.825 | J286: 121.2 | K286: 18.77 | L286: 78.72 | M286: 33.53 | N286: 120.55 | O286: 32.74 | P286: 12.93 | Q286: 83.121 | R286: 78.18 | S286: 74.76 | T286: 15.616 | U286: 73.2 | V286: 533 | W286: 78.7 | X286: 501.9 | Y286: 27.4375 | Z286: 17.992 | AA286: 299 | AB286: 9.554 | AC286: 41.75 | AD286: 151.95 | AE286: 869.6 | AF286: 32.955 | AG286: 106.15 | AH286: 81.0583 | AI286: 42.03 | AJ286: 11.9575 | AK286: 32.69 | AL286: 124.7 | AM286: 35.35 | AN286: 57.5 | AO286: 21.5589 | AP286: 5472.36 | AR286: 1.2139 | AS286: 0.88769 | AT286: 125.95 | AW286: 50.17 | AZ286: 44215 | BA286: 1.2129 | BB286: 0.88984 | BC286: 126.02
A287: 44222 | B287: 27.78 | C287: 9.674 | D287: 101.3899 | E287: 85.29 | F287: 55.38 | G287: 41.99 | H287: 21.87 | I287: 14.665 | J287: 121.7 | K287: 18.856 | L287: 77.98 | M287: 33.94 | N287: 120.7 | O287: 32.8 | P287: 12.99 | Q287: 83.076 | R287: 79.88 | S287: 74.5 | T287: 15.986 | U287: 73.36 | V287: 545.7 | W287: 79.6 | X287: 508 | Y287: 27.7875 | Z287: 18.35 | AA287: 301.8 | AB287: 9.702 | AC287: 41.98 | AD287: 153.9 | AE287: 870 | AF287: 34.025 | AG287: 108 | AH287: 80.6306 | AI287: 41.94 | AJ287: 12.1776 | AK287: 32.7 | AL287: 125.6 | AM287: 35.98 | AN287: 59.98 | AO287: 21.3757 | AP287: 5523.52 | AR287: 1.216 | AS287: 0.88524 | AT287: 126 | AW287: 50.04 | AZ287: 44216 | BA287: 1.2106 | BB287: 0.88656 | BC287: 125.35
A288: 44223 | B288: 27.74 | C288: 9.428 | D288: 102.5545 | E288: 84.36 | F288: 55.2 | G288: 40.525 | H288: 21.54 | I288: 14.425 | J288: 119.5 | K288: 18.674 | L288: 76.84 | M288: 33.83 | N288: 118.35 | O288: 32.46 | P288: 12.73 | Q288: 83.121 | R288: 80.96 | S288: 73.76 | T288: 15.564 | U288: 74.28 | V288: 541.6 | W288: 78.08 | X288: 506.4 | Y288: 27.125 | Z288: 17.578 | AA288: 297.6 | AB288: 9.854 | AC288: 41.55 | AD288: 152.95 | AE288: 854.2 | AF288: 34.22 | AG288: 105.95 | AH288: 78.6414 | AI288: 40.82 | AJ288: 11.7602 | AK288: 31.72 | AL288: 123.1 | AM288: 35.825 | AN288: 71.9 | AO288: 21.0961 | AP288: 5459.62 | AR288: 1.2111 | AS288: 0.8849 | AT288: 126.09 | AW288: 50.31 | AZ288: 44217 | BA288: 1.2164 | BB288: 0.88594 | BC288: 125.93
A289: 44224 | B289: 28.54 | C289: 9.57 | D289: 102.4793 | E289: 85.15 | F289: 55.28 | G289: 41.205 | H289: 21.91 | I289: 14.335 | J289: 119.5 | K289: 18.796 | L289: 78.68 | M289: 33.17 | N289: 117.9 | O289: 33.3 | P289: 12.96 | Q289: 82.711 | R289: 82.5 | S289: 76.22 | T289: 15.77 | U289: 73.98 | V289: 555.9 | W289: 77.76 | X289: 517 | Y289: 27.7125 | Z289: 18.48 | AA289: 297.4 | AB289: 9.802 | AC289: 42.5 | AD289: 157.85 | AE289: 861.6 | AF289: 35.4 | AG289: 106.3 | AH289: 78.6613 | AI289: 41.61 | AJ289: 12.0372 | AK289: 33.03 | AL289: 123.8 | AM289: 35.815 | AN289: 70.84 | AO289: 21.6071 | AP289: 5510.52 | AR289: 1.2122 | AS289: 0.8833 | AT289: 126.35 | AW289: 49.97 | AZ289: 44218 | BA289: 1.2171 | BB289: 0.88982 | BC289: 126.33
A290: 44225 | B290: 27.83 | C290: 9.38 | D290: 101.4275 | E290: 83.2 | F290: 54.96 | G290: 39.78 | H290: 21.69 | I290: 13.99 | J290: 119.5 | K290: 18.3 | L290: 76.58 | M290: 32.95 | N290: 117 | O290: 32.42 | P290: 12.82 | Q290: 81.113 | R290: 79.18 | S290: 74.94 | T290: 15.438 | U290: 74.18 | V290: 541.6 | W290: 75.9 | X290: 498.3 | Y290: 28.475 | Z290: 18.042 | AA290: 290.1 | AB290: 9.704 | AC290: 42.76 | AD290: 155.7 | AE290: 842.6 | AF290: 35.24 | AG290: 104.1 | AH290: 76.7318 | AI290: 41.08 | AJ290: 11.8702 | AK290: 33.27 | AL290: 120.95 | AM290: 34.895 | AN290: 69.5 | AO290: 21.2696 | AP290: 5399.21 | AR290: 1.2136 | AS290: 0.88555 | AT290: 127.13 | AW290: 49.93 | AZ290: 44221 | BA290: 1.2139 | BB290: 0.88769 | BC290: 125.95
A291: 44228 | B291: 27.89 | C291: 9.516 | D291: 102.2539 | E291: 83.11 | F291: 55.6 | G291: 40.18 | H291: 21.87 | I291: 14.1 | J291: 122.25 | K291: 18.454 | L291: 77.92 | M291: 33.55 | N291: 120.5 | O291: 33.07 | P291: 12.975 | Q291: 84.217 | R291: 80.84 | S291: 77.4 | T291: 15.584 | U291: 74.6 | V291: 543 | W291: 76.64 | X291: 507.7 | Y291: 28.55 | Z291: 18.402 | AA291: 296.5 | AB291: 9.726 | AC291: 43.75 | AD291: 156.95 | AE291: 854.2 | AF291: 35.035 | AG291: 102.95 | AH291: 77.7861 | AI291: 41.64 | AJ291: 11.9499 | AK291: 33.92 | AL291: 123.4 | AM291: 34.555 | AN291: 66.5 | AO291: 21.4721 | AP291: 5461.68 | AR291: 1.206 | AS291: 0.88267 | AT291: 126.55 | AW291: 50.38 | AZ291: 44222 | BA291: 1.216 | BB291: 0.88524 | BC291: 126
A292: 44229 | B292: 28.98 | C292: 9.796 | D292: 102.0661 | E292: 88.59 | F292: 54.68 | G292: 41.605 | H292: 22.29 | I292: 14.27 | J292: 124.75 | K292: 18.816 | L292: 80.16 | M292: 34.25 | N292: 123.05 | O292: 33.56 | P292: 13.035 | Q292: 86.819 | R292: 82.65 | S292: 79.06 | T292: 16.136 | U292: 76.84 | V292: 549.2 | W292: 77.56 | X292: 524.9 | Y292: 28.6125 | Z292: 18.218 | AA292: 298.4 | AB292: 9.716 | AC292: 43.75 | AD292: 159.7 | AE292: 884.8 | AF292: 35.98 | AG292: 107.85 | AH292: 78.174 | AI292: 42.05 | AJ292: 12.299 | AK292: 33.95 | AL292: 125.9 | AM292: 34.87 | AN292: 65.9 | AO292: 21.8481 | AP292: 5563.11 | AR292: 1.2044 | AS292: 0.88116 | AT292: 126.43 | AW292: 50.61 | AZ292: 44223 | BA292: 1.2111 | BB292: 0.8849 | BC292: 126.09
... A1315: 45660 | B1315: 45.99 | C1315: 13.215 | D1315: 140.5818 | E1315: 158.58 | F1315: 64.74 | G1315: 58.49 | H1315: 28.9 | I1315: 13.535 | J1315: 155 | K1315: 34.07 | L1315: 98.92 | M1315: 32.52 | N1315: 230.2 | O1315: 28.73 | P1315: 15.62 | Q1315: 107.4 | R1315: 48.57 | S1315: 83.38 | T1315: 26.525 | U1315: 136.7 | V1315: 224.35 | W1315: 92.54 | X1315: 611.3 | Y1315: 31.32 | Z1315: 21.46 | AA1315: 332 | AB1315: 9.636 | AC1315: 100.45 | AD1315: 105.25 | AE1315: 2237 | AF1315: 46.08 | AG1315: 211.6 | AH1315: 92.87 | AI1315: 83.9 | AJ1315: 12.184 | AK1315: 23.48 | AL1315: 240.2 | AM1315: 54 | AN1315: 73.74 | AO1315: 26.72 | AP1315: 7282.22 | AR1315: 1.0308 | AS1315: 0.82967 | AT1315: 162.08 | AW1315: 70.59 | AZ1315: 45656 | BA1315: 1.0407 | BB1315: 0.82916 | BC1315: 163.26
A1316: 45663 | B1316: 46.58 | C1316: 13.36 | D1316: 143.8 | E1316: 159.64 | F1316: 64.54 | G1316: 60.03 | H1316: 29.04 | I1316: 13.77 | J1316: 159.55 | K1316: 34.45 | L1316: 99.96 | M1316: 34.24 | N1316: 233 | O1316: 28.78 | P1316: 15.645 | Q1316: 107.3 | R1316: 49.66 | S1316: 83.9 | T1316: 27.35 | U1316: 137.75 | V1316: 229.85 | W1316: 95.66 | X1316: 634.6 | Y1316: 31.89 | Z1316: 21.52 | AA1316: 338 | AB1316: 9.618 | AC1316: 99.8 | AD1316: 108.4 | AE1316: 2338 | AF1316: 47 | AG1316: 213.7 | AH1316: 94.66 | AI1316: 86.3 | AJ1316: 12.644 | AK1316: 25.325 | AL1316: 251.15 | AM1316: 54.71 | AN1316: 74.3 | AO1316: 27.17 | AP1316: 7445.69 | AZ1316: 45657 | BA1316: 1.0354 | BB1316: 0.82746 | BC1316: 162.78
A1317: 45664 | B1317: 46.49 | C1317: 13.385 | D1317: 144.7818 | E1317: 158.4 | F1317: 65.54 | G1317: 60.4 | H1317: 28.86 | I1317: 13.815 | J1317: 160.4 | K1317: 34.76 | L1317: 101.15 | M1317: 34.51 | N1317: 234.8 | O1317: 28.87 | P1317: 15.72 | Q1317: 108.1 | R1317: 50.3 | S1317: 84.22 | T1317: 27.045 | U1317: 139.55 | V1317: 231.85 | W1317: 95.52 | X1317: 644.5 | Y1317: 31.69 | Z1317: 21.34 | AA1317: 336.25 | AB1317: 9.616 | AC1317: 99.32 | AD1317: 108.75 | AE1317: 2365 | AF1317: 47.31 | AG1317: 215.9 | AH1317: 95.85 | AI1317: 85.3 | AJ1317: 12.778 | AK1317: 25.815 | AL1317: 253.05 | AM1317: 54.98 | AN1317: 75.3 | AO1317: 27.17 | AP1317: 7489.35 | AZ1317: 45658 | BA1317: 1.0356 | BB1317: 0.82746 | BC1317: 162.91
A1318: 45665 | B1318: 46.69 | C1318: 13.36 | D1318: 143.3091 | E1318: 158.58 | F1318: 64.76 | G1318: 60.14 | H1318: 28.74 | I1318: 13.815 | J1318: 157.75 | K1318: 34.85 | L1318: 99.74 | M1318: 34.35 | N1318: 233.8 | O1318: 28.8 | P1318: 15.715 | Q1318: 108.9 | R1318: 48.2 | S1318: 83.4 | T1318: 27.585 | U1318: 145.45 | V1318: 226.7 | W1318: 95.6 | X1318: 635.7 | Y1318: 31.53 | Z1318: 21.15 | AA1318: 331.45 | AB1318: 9.606 | AC1318: 99.2 | AD1318: 108 | AE1318: 2370 | AF1318: 47.15 | AG1318: 216.2 | AH1318: 95.67 | AI1318: 85.24 | AJ1318: 12.456 | AK1318: 24.7 | AL1318: 251.4 | AM1318: 55.16 | AN1318: 74.7 | AO1318: 27 | AP1318: 7452.42 | AZ1318: 45659 | BA1318: 1.0265 | BB1318: 0.82923 | BC1318: 161.71
...

Sheet Returns
A1: Début | B1: 43831 | F1: 214
A2: Fin
A3: ROI | B3: 5.2505052 | C3: 0.93503072 | D3: 9.1724679 | E3: 14.21356 | F3: 6.8505481 | G3: 2.1957615 | H3: 14.805947 | I3: 5.8134306 | J3: 7.4301633 | K3: 3.8440551 | L3: 7.8274275 | M3: 10.718121 | N3: 4.855415 | O3: 5.5379046 | P3: 5.4611829 | Q3: 9.1927588 | R3: 7.1387091 | S3: 6.6104918 | T3: 1.2844051 | U3: 11.598615 | V3: -0.30825678 | W3: 9.282531 | X3: 9.9304404 | Y3: 6.8273297 | Z3: 3.6892833 | AA3: 13.518798 | AB3: 7.0163417 | AC3: 11.350183 | AD3: 5.1808401 | AE3: 22.018988 | AF3: 1.2727701 | AG3: 13.641934 | AH3: 4.7665285 | AI3: 7.7627652 | AJ3: -17.137947 | AK3: 1.76546 | AL3: 11.523608 | AM3: 8.619193 | AN3: 5.0216166 | AO3: 5.3558281
A4: WACC en % | B4: 14.367405 | C4: 12.185419 | D4: 10.88195 | E4: 13.343262 | F4: 8.4010396 | G4: 14.032748 | H4: 11.979887 | I4: 9.2732576 | J4: 13.385847 | K4: 11.849612 | L4: 12.481588 | M4: 11.272379 | N4: 13.082016 | O4: 11.632988 | P4: 9.0330867 | Q4: 10.387129 | R4: 13.072406 | S4: 12.670382 | T4: 14.861122 | U4: 11.679322 | V4: 15.848917 | W4: 12.803966 | X4: 14.371309 | Y4: 11.724103 | Z4: 18.343572 | AA4: 10.631104 | AB4: 6.4847822 | AC4: 11.489865 | AD4: 12.485264 | AE4: 14.568076 | AF4: 13.32931 | AG4: 13.935409 | AH4: 9.9015457 | AI4: 15.781893 | AJ4: 17.823856 | AK4: 6.6922265 | AL4: 16.789632 | AM4: 7.7187638 | AN4: 12.276331 | AO4: 11.569979 | AZ4: DEVISES
B5: ACCOR SA | C5: CREDIT AGRICOLE SA | D5: AIR LIQUIDE SA | E5: AIRBUS SE | F5: DANONE | G5: BNP PARIBAS | H5: BUREAU VERITAS SA | I5: CARREFOUR SA | J5: CAPGEMINI SE | K5: AXA SA | L5: VINCI SA | M5: DASSAULT SYSTEMES SE | N5: ESSILORLUXOTTICA | O5: BOUYGUES SA | P5: ENGIE | Q5: EURONEXT NV | R5: EUROFINS SCIENTIFIC | S5: EIFFAGE | T5: SOCIETE GENERALE SA | U5: THALES SA | V5: KERING | W5: LEGRAND SA | X5: LVMH MOET HENNESSY LOUIS VUI | Y5: MICHELIN (CGDE) | Z5: ARCELORMITTAL | AA5: L'OREAL | AB5: ORANGE | AC5: PUBLICIS GROUPE | AD5: PERNOD RICARD SA | AE5: HERMES INTERNATIONAL | AF5: RENAULT SA | AG5: SAFRAN SA | AH5: SANOFI | AI5: COMPAGNIE DE SAINT GOBAIN | AJ5: STELLANTIS NV | AK5: STMICROELECTRONICS NV | AL5: SCHNEIDER ELECTRIC SE | AM5: TOTALENERGIES SE | AN5: UNIBAIL-RODAMCO-WESTFIELD | AO5: VEOLIA ENVIRONNEMENT | AP5: CAC 40 INDEX | AR5: EUR-USD X-RATE | AS5: EUR-GBP X-RATE | AT5: EUR-JPY X-RATE | AW5: BRENT CRUDE FUTR Nov26
B6: AC FP | C6: ACA FP | D6: AI FP | E6: AIR FP | F6: BN FP | G6: BNP FP | H6: BVI FP | I6: CA FP | J6: CAP FP | K6: CS FP | L6: DG FP | M6: DSY FP | N6: EL FP | O6: EN FP | P6: ENGI FP | Q6: ENX FP | R6: ERF FP | S6: FGR FP | T6: GLE FP | U6: HO FP | V6: KER FP | W6: LR FP | X6: MC FP | Y6: ML FP | Z6: MT NA | AA6: OR FP | AB6: ORA FP | AC6: PUB FP | AD6: RI FP | AE6: RMS FP | AF6: RNO FP | AG6: SAF FP | AH6: SAN FP | AI6: SGO FP | AJ6: STLAP FP | AK6: STMPA FP | AL6: SU FP | AM6: TTE FP | AN6: URW FP | AO6: VIE FP | AP6: CAC Index | AR6: EURUSD Curncy | AS6: EURGBP Curncy | AT6: EURJPY Curncy | AW6: COA Comdty | AZ6: Date de début | BA6: 43831
B7: AC FP Equity | C7: ACA FP Equity | D7: AI FP Equity | E7: AIR FP Equity | F7: BN FP Equity | G7: BNP FP Equity | H7: BVI FP Equity | I7: CA FP Equity | J7: CAP FP Equity | K7: CS FP Equity | L7: DG FP Equity | M7: DSY FP Equity | N7: EL FP Equity | O7: EN FP Equity | P7: ENGI FP Equity | Q7: ENX FP Equity | R7: ERF FP Equity | S7: FGR FP Equity | T7: GLE FP Equity | U7: HO FP Equity | V7: KER FP Equity | W7: LR FP Equity | X7: MC FP Equity | Y7: ML FP Equity | Z7: MT NA Equity | AA7: OR FP Equity | AB7: ORA FP Equity | AC7: PUB FP Equity | AD7: RI FP Equity | AE7: RMS FP Equity | AF7: RNO FP Equity | AG7: SAF FP Equity | AH7: SAN FP Equity | AI7: SGO FP Equity | AJ7: STLAP FP Equity | AK7: STMPA FP Equity | AL7: SU FP Equity | AM7: TTE FP Equity | AN7: URW FP Equity | AO7: VIE FP Equity | AP7: CAC Index | AR7: EURUSD Curncy | AS7: EURGBP Curncy | AT7: EURJPY Curncy | AW7: COA Comdty | AZ7: Date de fin
A8: 43831 | AR8: 1.1212 | AS8: 0.84624 | AT8: 121.92 | AW8: 58.53 | BA8: EUR-USD X-RATE | BB8: EUR-GBP X-RATE | BC8: EUR-JPY X-RATE
A9: 43832 | B9: =LN('Data Daily'!B9/'Data Daily'!B8) -> 0.00023949228 | C9: =LN('Data Daily'!C9/'Data Daily'!C8) -> 0.019916399 | D9: =LN('Data Daily'!D9/'Data Daily'!D8) -> 0.0039545859 | E9: =LN('Data Daily'!E9/'Data Daily'!E8) -> 0.023031321 | F9: =LN('Data Daily'!F9/'Data Daily'!F8) -> 0.0010819585 | G9: =LN('Data Daily'!G9/'Data Daily'!G8) -> 0.014096653 | H9: =LN('Data Daily'!H9/'Data Daily'!H8) -> 0.015781944 | I9: =LN('Data Daily'!I9/'Data Daily'!I8) -> 0.0013368986 | ... U9: =LN('Data Daily'!U9/'Data Daily'!U8) -> 0.0045292863 | AR9: 1.1172 | AS9: 0.84994 | AT9: 121.32 | AW9: 58.95 | BA9: EURUSD Curncy | BB9: EURGBP Curncy | BC9: EURJPY Curncy
A10: 43833 | B10: =LN('Data Daily'!B10/'Data Daily'!B9) -> -0.013257998 | C10: =LN('Data Daily'!C10/'Data Daily'!C9) -> -0.006085983 | D10: =LN('Data Daily'!D10/'Data Daily'!D9) -> -0.0031617843 | E10: =LN('Data Daily'!E10/'Data Daily'!E9) -> 0.0038869835 | F10: =LN('Data Daily'!F10/'Data Daily'!F9) -> 0.0086137814 | G10: =LN('Data Daily'!G10/'Data Daily'!G9) -> -0.012016667 | H10: =LN('Data Daily'!H10/'Data Daily'!H9) -> -0.0016941978 | I10: =LN('Data Daily'!I10/'Data Daily'!I9) -> 0.0040000053 | ... U10: =LN('Data Daily'!U10/'Data Daily'!U9) -> 0.01261644 | AR10: 1.1161 | AS10: 0.85335 | AT10: 120.49 | AW10: 58.53
A11: 43836 | B11: =LN('Data Daily'!B11/'Data Daily'!B10) -> -0.023570941 | C11: =LN('Data Daily'!C11/'Data Daily'!C10) -> -0.0099694077 | D11: =LN('Data Daily'!D11/'Data Daily'!D10) -> -0.0067536281 | E11: =LN('Data Daily'!E11/'Data Daily'!E10) -> -0.0043364554 | F11: =LN('Data Daily'!F11/'Data Daily'!F10) -> 0.0018744148 | G11: =LN('Data Daily'!G11/'Data Daily'!G10) -> -0.0049233199 | H11: =LN('Data Daily'!H11/'Data Daily'!H10) -> -0.0059523985 | I11: =LN('Data Daily'!I11/'Data Daily'!I10) -> 0 | ... U11: =LN('Data Daily'!U11/'Data Daily'!U10) -> 0.0097272918 | AR11: 1.1197 | AS11: 0.85023 | AT11: 121.33 | AW11: 58.5 | AZ11: Dates | BA11: LAST_price | BB11: LAST_price | BC11: LAST_price
A12: 43837 | B12: =LN('Data Daily'!B12/'Data Daily'!B11) -> 0.0024813909 | C12: =LN('Data Daily'!C12/'Data Daily'!C11) -> -0.0023148158 | D12: =LN('Data Daily'!D12/'Data Daily'!D11) -> -0.004393611 | E12: =LN('Data Daily'!E12/'Data Daily'!E11) -> -0.010999885 | F12: =LN('Data Daily'!F12/'Data Daily'!F11) -> -0.0094074071 | G12: =LN('Data Daily'!G12/'Data Daily'!G11) -> -0.00037972281 | H12: =LN('Data Daily'!H12/'Data Daily'!H11) -> -0.0021344725 | I12: =LN('Data Daily'!I12/'Data Daily'!I11) -> 0.0079523282 | ... U12: =LN('Data Daily'!U12/'Data Daily'!U11) -> -0.0025284464 | AR12: 1.1153 | AS12: 0.84984 | AT12: 120.92 | AW12: 58.89 | AZ12: 43831 | BA12: 1.1212 | BB12: 0.84624 | BC12: 121.92
A13: 43838 | B13: =LN('Data Daily'!B13/'Data Daily'!B12) -> 0.0012383903 | C13: =LN('Data Daily'!C13/'Data Daily'!C12) -> 0.0046242857 | D13: =LN('Data Daily'!D13/'Data Daily'!D12) -> 0.00080104993 | E13: =LN('Data Daily'!E13/'Data Daily'!E12) -> 0.017869685 | F13: =LN('Data Daily'!F13/'Data Daily'!F12) -> -0.02046177 | G13: =LN('Data Daily'!G13/'Data Daily'!G12) -> 0.002276177 | H13: =LN('Data Daily'!H13/'Data Daily'!H12) -> 0.0055401804 | I13: =LN('Data Daily'!I13/'Data Daily'!I12) -> 0.0013192614 | ... U13: =LN('Data Daily'!U13/'Data Daily'!U12) -> 0.014452027 | AR13: 1.1105 | AS13: 0.84803 | AT13: 121.18 | AW13: 58.34 | AZ13: 43832 | BA13: 1.1172 | BB13: 0.84994 | BC13: 121.32
A14: 43839 | B14: =LN('Data Daily'!B14/'Data Daily'!B13) -> 0.0044455494 | C14: =LN('Data Daily'!C14/'Data Daily'!C13) -> 0.00076863955 | D14: =LN('Data Daily'!D14/'Data Daily'!D13) -> 0.0039914104 | E14: =LN('Data Daily'!E14/'Data Daily'!E13) -> 0.0040104027 | F14: =LN('Data Daily'!F14/'Data Daily'!F13) -> 0.0019275787 | G14: =LN('Data Daily'!G14/'Data Daily'!G13) -> -0.0072257397 | H14: =LN('Data Daily'!H14/'Data Daily'!H13) -> 0.0042408885 | I14: =LN('Data Daily'!I14/'Data Daily'!I13) -> 0.00098830514 | ... U14: =LN('Data Daily'!U14/'Data Daily'!U13) -> 0.0033215725 | AR14: 1.1106 | AS14: 0.84994 | AT14: 121.63 | AW14: 58.54 | AZ14: 43833 | BA14: 1.1161 | BB14: 0.85335 | BC14: 120.49
A15: 43840 | B15: =LN('Data Daily'!B15/'Data Daily'!B14) -> -0.0024673094 | C15: =LN('Data Daily'!C15/'Data Daily'!C14) -> -0.010815092 | D15: =LN('Data Daily'!D15/'Data Daily'!D14) -> 0.0023876447 | E15: =LN('Data Daily'!E15/'Data Daily'!E14) -> -0.0037127837 | F15: =LN('Data Daily'!F15/'Data Daily'!F14) -> -0.0013764627 | G15: =LN('Data Daily'!G15/'Data Daily'!G14) -> -0.0045906737 | H15: =LN('Data Daily'!H15/'Data Daily'!H14) -> -0.0080731265 | I15: =LN('Data Daily'!I15/'Data Daily'!I14) -> -0.011258397 | ... U15: =LN('Data Daily'!U15/'Data Daily'!U14) -> -0.0060284976 | AR15: 1.1121 | AS15: 0.85115 | AT15: 121.65 | AW15: 58.17 | AZ15: 43836 | BA15: 1.1197 | BB15: 0.85023 | BC15: 121.33
A16: 43843 | B16: =LN('Data Daily'!B16/'Data Daily'!B15) -> -0.0034644925 | C16: =LN('Data Daily'!C16/'Data Daily'!C15) -> -0.0015546058 | D16: =LN('Data Daily'!D16/'Data Daily'!D15) -> 0.0035708119 | E16: =LN('Data Daily'!E16/'Data Daily'!E15) -> 0.005194046 | F16: =LN('Data Daily'!F16/'Data Daily'!F15) -> -0.0046941961 | G16: =LN('Data Daily'!G16/'Data Daily'!G15) -> -0.0044192598 | H16: =LN('Data Daily'!H16/'Data Daily'!H15) -> 0.036855092 | I16: =LN('Data Daily'!I16/'Data Daily'!I15) -> 0.0023282898 | ... U16: =LN('Data Daily'!U16/'Data Daily'!U15) -> 0.0089258506 | AR16: 1.1134 | AS16: 0.85723 | AT16: 122.42 | AW16: 58.1 | AZ16: 43837 | BA16: 1.1153 | BB16: 0.84984 | BC16: 120.92
A17: 43844 | B17: =LN('Data Daily'!B17/'Data Daily'!B16) -> 0.016472407 | C17: =LN('Data Daily'!C17/'Data Daily'!C16) -> 0.0050436576 | D17: =LN('Data Daily'!D17/'Data Daily'!D16) -> 0.0059231636 | E17: =LN('Data Daily'!E17/'Data Daily'!E16) -> -0.00014802753 | F17: =LN('Data Daily'!F17/'Data Daily'!F16) -> -0.011972856 | G17: =LN('Data Daily'!G17/'Data Daily'!G16) -> 0.0046109592 | H17: =LN('Data Daily'!H17/'Data Daily'!H16) -> 0.0057400732 | I17: =LN('Data Daily'!I17/'Data Daily'!I16) -> 0.0033167526 | ... U17: =LN('Data Daily'!U17/'Data Daily'!U16) -> -0.0033119467 | AR17: 1.1128 | AS17: 0.85476 | AT17: 122.4 | AW17: 58.23 | AZ17: 43838 | BA17: 1.1105 | BB17: 0.84803 | BC17: 121.18
A18: 43845 | B18: =LN('Data Daily'!B18/'Data Daily'!B17) -> -0.010540605 | C18: =LN('Data Daily'!C18/'Data Daily'!C17) -> -0.012069448 | D18: =LN('Data Daily'!D18/'Data Daily'!D17) -> -0.0015764329 | E18: =LN('Data Daily'!E18/'Data Daily'!E17) -> -0.0062370265 | F18: =LN('Data Daily'!F18/'Data Daily'!F17) -> 0.014460764 | G18: =LN('Data Daily'!G18/'Data Daily'!G17) -> -0.023466606 | H18: =LN('Data Daily'!H18/'Data Daily'!H17) -> 0.010573502 | I18: =LN('Data Daily'!I18/'Data Daily'!I17) -> -0.0049792634 | ... U18: =LN('Data Daily'!U18/'Data Daily'!U17) -> -0.0014524331 | AR18: 1.115 | AS18: 0.85519 | AT18: 122.55 | AW18: 58.1 | AZ18: 43839 | BA18: 1.1106 | BB18: 0.84994 | BC18: 121.63
A19: 43846 | B19: =LN('Data Daily'!B19/'Data Daily'!B18) -> -0.0079169142 | C19: =LN('Data Daily'!C19/'Data Daily'!C18) -> 0.0007830854 | D19: =LN('Data Daily'!D19/'Data Daily'!D18) -> 0.0043279183 | E19: =LN('Data Daily'!E19/'Data Daily'!E18) -> -0.006426085 | F19: =LN('Data Daily'!F19/'Data Daily'!F18) -> 0.014526773 | G19: =LN('Data Daily'!G19/'Data Daily'!G18) -> -0.007287083 | H19: =LN('Data Daily'!H19/'Data Daily'!H18) -> 0.0028277135 | I19: =LN('Data Daily'!I19/'Data Daily'!I18) -> -0.012726227 | ... U19: =LN('Data Daily'!U19/'Data Daily'!U18) -> 0.010123008 | AR19: 1.1137 | AS19: 0.85155 | AT19: 122.68 | AW19: 58.24 | AZ19: 43840 | BA19: 1.1121 | BB19: 0.85115 | BC19: 121.65
A20: 43847 | B20: =LN('Data Daily'!B20/'Data Daily'!B19) -> -0.0014914246 | C20: =LN('Data Daily'!C20/'Data Daily'!C19) -> 0.0074088855 | D20: =LN('Data Daily'!D20/'Data Daily'!D19) -> 0.015969235 | E20: =LN('Data Daily'!E20/'Data Daily'!E19) -> 0.025021662 | F20: =LN('Data Daily'!F20/'Data Daily'!F19) -> 0.002717393 | G20: =LN('Data Daily'!G20/'Data Daily'!G19) -> 0.0031576896 | H20: =LN('Data Daily'!H20/'Data Daily'!H19) -> 0.016403648 | I20: =LN('Data Daily'!I20/'Data Daily'!I19) -> -0.005746171 | ... U20: =LN('Data Daily'!U20/'Data Daily'!U19) -> 0.015096166 | AR20: 1.1092 | AS20: 0.85201 | AT20: 122.19 | AW20: 58.22 | AZ20: 43843 | BA20: 1.1134 | BB20: 0.85723 | BC20: 122.42
A21: 43850 | B21: =LN('Data Daily'!B21/'Data Daily'!B20) -> -0.020608922 | C21: =LN('Data Daily'!C21/'Data Daily'!C20) -> -0.0046729057 | D21: =LN('Data Daily'!D21/'Data Daily'!D20) -> -0.0042592075 | E21: =LN('Data Daily'!E21/'Data Daily'!E20) -> 0.0081549891 | F21: =LN('Data Daily'!F21/'Data Daily'!F20) -> -0.0065341915 | G21: =LN('Data Daily'!G21/'Data Daily'!G20) -> -0.0051363211 | H21: =LN('Data Daily'!H21/'Data Daily'!H20) -> -0.005970167 | I21: =LN('Data Daily'!I21/'Data Daily'!I20) -> 0 | ... U21: =LN('Data Daily'!U21/'Data Daily'!U20) -> 0.011274531 | AR21: 1.1095 | AS21: 0.85284 | AT21: 122.25 | AW21: 58.25 | AZ21: 43844 | BA21: 1.1128 | BB21: 0.85476 | BC21: 122.4
A22: 43851 | B22: =LN('Data Daily'!B22/'Data Daily'!B21) -> -0.01380743 | C22: =LN('Data Daily'!C22/'Data Daily'!C21) -> -0.0035190652 | D22: =LN('Data Daily'!D22/'Data Daily'!D21) -> 0.0065749746 | E22: =LN('Data Daily'!E22/'Data Daily'!E21) -> -0.010937039 | F22: =LN('Data Daily'!F22/'Data Daily'!F21) -> 0.0010920012 | G22: =LN('Data Daily'!G22/'Data Daily'!G21) -> -0.0055610868 | H22: =LN('Data Daily'!H22/'Data Daily'!H21) -> -0.0015980826 | I22: =LN('Data Daily'!I22/'Data Daily'!I21) -> 0.00033892561 | ... U22: =LN('Data Daily'!U22/'Data Daily'!U21) -> -0.0088478357 | AR22: 1.1082 | AS22: 0.84938 | AT22: 121.77 | AW22: 58.51 | AZ22: 43845 | BA22: 1.115 | BB22: 0.85519 | BC22: 122.55
A23: 43852 | B23: =LN('Data Daily'!B23/'Data Daily'!B22) -> -0.0064574679 | C23: =LN('Data Daily'!C23/'Data Daily'!C22) -> -0.010632114 | D23: =LN('Data Daily'!D23/'Data Daily'!D22) -> -0.0011572132 | E23: =LN('Data Daily'!E23/'Data Daily'!E22) -> 0.011517002 | F23: =LN('Data Daily'!F23/'Data Daily'!F22) -> -0.0054719699 | G23: =LN('Data Daily'!G23/'Data Daily'!G22) -> -0.0025924833 | H23: =LN('Data Daily'!H23/'Data Daily'!H22) -> 0.0091542928 | I23: =LN('Data Daily'!I23/'Data Daily'!I22) -> -0.020541633 | ... U23: =LN('Data Daily'!U23/'Data Daily'!U22) -> -0.0070943847 | AR23: 1.1093 | AS23: 0.84414 | AT23: 121.83 | AW23: 58.09 | AZ23: 43846 | BA23: 1.1137 | BB23: 0.85155 | BC23: 122.68
... A1315: 45660 | B1315: =LN('Data Daily'!B1315/'Data Daily'!B1314) -> -0.024485759 | C1315: =LN('Data Daily'!C1315/'Data Daily'!C1314) -> -0.0094144924 | D1315: =LN('Data Daily'!D1315/'Data Daily'!D1314) -> -0.0078583987 | E1315: =LN('Data Daily'!E1315/'Data Daily'!E1314) -> -0.0097892348 | F1315: =LN('Data Daily'!F1315/'Data Daily'!F1314) -> -0.0021601613 | G1315: =LN('Data Daily'!G1315/'Data Daily'!G1314) -> -0.012909981 | H1315: =LN('Data Daily'!H1315/'Data Daily'!H1314) -> -0.0062090575 | I1315: =LN('Data Daily'!I1315/'Data Daily'!I1314) -> -0.0095588963 | ... U1315: =LN('Data Daily'!U1315/'Data Daily'!U1314) -> -0.0065621818 | AR1315: 1.0308 | AS1315: 0.82967 | AT1315: 162.08 | AW1315: 70.59 | AZ1315: 45656 | BA1315: 1.0407 | BB1315: 0.82916 | BC1315: 163.26
A1316: 45663 | B1316: =LN('Data Daily'!B1316/'Data Daily'!B1315) -> 0.012747283 | C1316: =LN('Data Daily'!C1316/'Data Daily'!C1315) -> 0.01091262 | D1316: =LN('Data Daily'!D1316/'Data Daily'!D1315) -> 0.02263392 | E1316: =LN('Data Daily'!E1316/'Data Daily'!E1315) -> 0.0066620823 | F1316: =LN('Data Daily'!F1316/'Data Daily'!F1315) -> -0.0030940619 | G1316: =LN('Data Daily'!G1316/'Data Daily'!G1315) -> 0.025988638 | H1316: =LN('Data Daily'!H1316/'Data Daily'!H1315) -> 0.0048325948 | I1316: =LN('Data Daily'!I1316/'Data Daily'!I1315) -> 0.01721339 | ... U1316: =LN('Data Daily'!U1316/'Data Daily'!U1315) -> 0.0076517043 | AZ1316: 45657 | BA1316: 1.0354 | BB1316: 0.82746 | BC1316: 162.78
A1317: 45664 | B1317: =LN('Data Daily'!B1317/'Data Daily'!B1316) -> -0.0019340288 | C1317: =LN('Data Daily'!C1317/'Data Daily'!C1316) -> 0.0018695089 | D1317: =LN('Data Daily'!D1317/'Data Daily'!D1316) -> 0.0068043362 | E1317: =LN('Data Daily'!E1317/'Data Daily'!E1316) -> -0.0077978008 | F1317: =LN('Data Daily'!F1317/'Data Daily'!F1316) -> 0.015375457 | G1317: =LN('Data Daily'!G1317/'Data Daily'!G1316) -> 0.0061446677 | H1317: =LN('Data Daily'!H1317/'Data Daily'!H1316) -> -0.0062176366 | I1317: =LN('Data Daily'!I1317/'Data Daily'!I1316) -> 0.0032626456 | ... U1317: =LN('Data Daily'!U1317/'Data Daily'!U1316) -> 0.012982512 | AZ1317: 45658 | BA1317: 1.0356 | BB1317: 0.82746 | BC1317: 162.91
A1318: 45665 | B1318: =LN('Data Daily'!B1318/'Data Daily'!B1317) -> 0.0042927733 | C1318: =LN('Data Daily'!C1318/'Data Daily'!C1317) -> -0.0018695089 | D1318: =LN('Data Daily'!D1318/'Data Daily'!D1317) -> -0.010223945 | E1318: =LN('Data Daily'!E1318/'Data Daily'!E1317) -> 0.0011357185 | F1318: =LN('Data Daily'!F1318/'Data Daily'!F1317) -> -0.011972514 | G1318: =LN('Data Daily'!G1318/'Data Daily'!G1317) -> -0.0043139274 | H1318: =LN('Data Daily'!H1318/'Data Daily'!H1317) -> -0.0041666727 | I1318: =LN('Data Daily'!I1318/'Data Daily'!I1317) -> 0 | ... U1318: =LN('Data Daily'!U1318/'Data Daily'!U1317) -> 0.041409425 | AZ1318: 45659 | BA1318: 1.0265 | BB1318: 0.82923 | BC1318: 161.71
A1319: 45666 | B1319: =LN('Data Daily'!B1319/'Data Daily'!B1318) -> 0.011287523 | C1319: =LN('Data Daily'!C1319/'Data Daily'!C1318) -> 0.005598074 | D1319: =LN('Data Daily'!D1319/'Data Daily'!D1318) -> 0.0044309198 | E1319: =LN('Data Daily'!E1319/'Data Daily'!E1318) -> -0.012692136 | F1319: =LN('Data Daily'!F1319/'Data Daily'!F1318) -> 0.012277625 | G1319: =LN('Data Daily'!G1319/'Data Daily'!G1318) -> -0.0031642961 | H1319: =LN('Data Daily'!H1319/'Data Daily'!H1318) -> 0.026778119 | I1319: =LN('Data Daily'!I1319/'Data Daily'!I1318) -> -0.0061717386 | ... U1319: =LN('Data Daily'!U1319/'Data Daily'!U1318) -> -0.01140894 | AZ1319: 45660 | BA1319: 1.0308 | BB1319: 0.82967 | BC1319: 162.08
A1320: 45667 | B1320: =LN('Data Daily'!B1320/'Data Daily'!B1319) -> 0.00021175225 | C1320: =LN('Data Daily'!C1320/'Data Daily'!C1319) -> -0.0044759493 | D1320: =LN('Data Daily'!D1320/'Data Daily'!D1319) -> -0.014376303 | E1320: =LN('Data Daily'!E1320/'Data Daily'!E1319) -> 0.0062392766 | F1320: =LN('Data Daily'!F1320/'Data Daily'!F1319) -> -0.017852121 | G1320: =LN('Data Daily'!G1320/'Data Daily'!G1319) -> -0.01005876 | H1320: =LN('Data Daily'!H1320/'Data Daily'!H1319) -> 0.0074249413 | I1320: =LN('Data Daily'!I1320/'Data Daily'!I1319) -> -0.0025524171 | ... U1320: =LN('Data Daily'!U1320/'Data Daily'!U1319) -> 0.0024309788 | AZ1320: 45663 | BA1320: 1.039 | BB1320: 0.82985 | BC1320: 163.77
A1321: 45670 | B1321: =LN('Data Daily'!B1321/'Data Daily'!B1320) -> -0.0087188218 | C1321: =LN('Data Daily'!C1321/'Data Daily'!C1320) -> 0.0033588388 | D1321: =LN('Data Daily'!D1321/'Data Daily'!D1320) -> 0.0025592545 | E1321: =LN('Data Daily'!E1321/'Data Daily'!E1320) -> -0.013546533 | F1321: =LN('Data Daily'!F1321/'Data Daily'!F1320) -> -0.0065430986 | G1321: =LN('Data Daily'!G1321/'Data Daily'!G1320) -> 0.0048743688 | H1321: =LN('Data Daily'!H1321/'Data Daily'!H1320) -> -0.0026936043 | I1321: =LN('Data Daily'!I1321/'Data Daily'!I1320) -> 0.013057857 | ... U1321: =LN('Data Daily'!U1321/'Data Daily'!U1320) -> -0.00034692108 | AZ1321: 45664 | BA1321: 1.034 | BB1321: 0.82879 | BC1321: 163.42
A1322: 45671 | B1322: =LN('Data Daily'!B1322/'Data Daily'!B1321) -> 0.014629753 | C1322: =LN('Data Daily'!C1322/'Data Daily'!C1321) -> 0.01699339 | D1322: =LN('Data Daily'!D1322/'Data Daily'!D1321) -> -0.0037129183 | E1322: =LN('Data Daily'!E1322/'Data Daily'!E1321) -> 0.0034679888 | F1322: =LN('Data Daily'!F1322/'Data Daily'!F1321) -> -0.0043859719 | G1322: =LN('Data Daily'!G1322/'Data Daily'!G1321) -> 0.019427759 | H1322: =LN('Data Daily'!H1322/'Data Daily'!H1321) -> 0.0013477091 | I1322: =LN('Data Daily'!I1322/'Data Daily'!I1321) -> 0.0075390772 | ... U1322: =LN('Data Daily'!U1322/'Data Daily'!U1321) -> 0.0079488927 | AZ1322: 45665 | BA1322: 1.0318 | BB1322: 0.8346 | BC1322: 163.4
A1323: 45672 | B1323: =LN('Data Daily'!B1323/'Data Daily'!B1322) -> 0.0065037468 | C1323: =LN('Data Daily'!C1323/'Data Daily'!C1322) -> 0.015628157 | D1323: =LN('Data Daily'!D1323/'Data Daily'!D1322) -> 0.0032017317 | E1323: =LN('Data Daily'!E1323/'Data Daily'!E1322) -> -0.010310698 | F1323: =LN('Data Daily'!F1323/'Data Daily'!F1322) -> 0.0068836317 | G1323: =LN('Data Daily'!G1323/'Data Daily'!G1322) -> 0.020669627 | H1323: =LN('Data Daily'!H1323/'Data Daily'!H1322) -> 0.020000667 | I1323: =LN('Data Daily'!I1323/'Data Daily'!I1322) -> 0.015614228 | ... U1323: =LN('Data Daily'!U1323/'Data Daily'!U1322) -> 0.00068823127 | AZ1323: 45666 | BA1323: 1.03 | BB1323: 0.83682 | BC1323: 162.87
A1324: 45673 | B1324: =LN('Data Daily'!B1324/'Data Daily'!B1323) -> -0.0035613319 | C1324: =LN('Data Daily'!C1324/'Data Daily'!C1323) -> 0.0050359819 | D1324: =LN('Data Daily'!D1324/'Data Daily'!D1323) -> 0.011948853 | E1324: =LN('Data Daily'!E1324/'Data Daily'!E1323) -> 0.018101784 | F1324: =LN('Data Daily'!F1324/'Data Daily'!F1323) -> 0.0049766821 | G1324: =LN('Data Daily'!G1324/'Data Daily'!G1323) -> 0.0020918827 | H1324: =LN('Data Daily'!H1324/'Data Daily'!H1323) -> -0.0039682592 | I1324: =LN('Data Daily'!I1324/'Data Daily'!I1323) -> -0.011331566 | ... U1324: =LN('Data Daily'!U1324/'Data Daily'!U1323) -> 0.012307848 | AZ1324: 45667 | BA1324: 1.0244 | BB1324: 0.83898 | BC1324: 161.59
A1325: 45674 | B1325: =LN('Data Daily'!B1325/'Data Daily'!B1324) -> 0.0085676002 | C1325: =LN('Data Daily'!C1325/'Data Daily'!C1324) -> 0.0032240759 | D1325: =LN('Data Daily'!D1325/'Data Daily'!D1324) -> 0.020139713 | E1325: =LN('Data Daily'!E1325/'Data Daily'!E1324) -> 0.022518091 | F1325: =LN('Data Daily'!F1325/'Data Daily'!F1324) -> 0.0086500385 | G1325: =LN('Data Daily'!G1325/'Data Daily'!G1324) -> 0.00048212134 | H1325: =LN('Data Daily'!H1325/'Data Daily'!H1324) -> 0.0046281074 | I1325: =LN('Data Daily'!I1325/'Data Daily'!I1324) -> -0.050768616 | ... U1325: =LN('Data Daily'!U1325/'Data Daily'!U1324) -> 0.0091324836 | AZ1325: 45670 | BA1325: 1.0245 | BB1325: 0.83946 | BC1325: 161.32
A1326: 45677 | B1326: =LN('Data Daily'!B1326/'Data Daily'!B1325) -> 0.0041528299 | C1326: =LN('Data Daily'!C1326/'Data Daily'!C1325) -> 0.013852113 | D1326: =LN('Data Daily'!D1326/'Data Daily'!D1325) -> 0.0032144562 | E1326: =LN('Data Daily'!E1326/'Data Daily'!E1325) -> 0.016286603 | F1326: =LN('Data Daily'!F1326/'Data Daily'!F1325) -> 0.0064387774 | G1326: =LN('Data Daily'!G1326/'Data Daily'!G1325) -> 0.011342881 | H1326: =LN('Data Daily'!H1326/'Data Daily'!H1325) -> -0.0079470617 | I1326: =LN('Data Daily'!I1326/'Data Daily'!I1325) -> 0.014506485 | ... U1326: =LN('Data Daily'!U1326/'Data Daily'!U1325) -> 0.0073801073 | AZ1326: 45671 | BA1326: 1.0308 | BB1326: 0.84385 | BC1326: 162.83
A1327: 45678 | B1327: =LN('Data Daily'!B1327/'Data Daily'!B1326) -> 0.0012424934 | C1327: =LN('Data Daily'!C1327/'Data Daily'!C1326) -> -0.00035279591 | D1327: =LN('Data Daily'!D1327/'Data Daily'!D1326) -> -0.0071850525 | E1327: =LN('Data Daily'!E1327/'Data Daily'!E1326) -> -0.00073457398 | F1327: =LN('Data Daily'!F1327/'Data Daily'!F1326) -> -0.00030567018 | G1327: =LN('Data Daily'!G1327/'Data Daily'!G1326) -> 0.0025384751 | H1327: =LN('Data Daily'!H1327/'Data Daily'!H1326) -> 0.0086064748 | I1327: =LN('Data Daily'!I1327/'Data Daily'!I1326) -> -0.0051832771 | ... U1327: =LN('Data Daily'!U1327/'Data Daily'!U1326) -> 0.010307656 | AZ1327: 45672 | BA1327: 1.0289 | BB1327: 0.84054 | BC1327: 160.99
... A1760: 46283 | B1760: =LN('Data Daily'!B1760/'Data Daily'!B1759) -> -0.0037227679 | C1760: =LN('Data Daily'!C1760/'Data Daily'!C1759) -> -0.022558369 | D1760: =LN('Data Daily'!D1760/'Data Daily'!D1759) -> -0.012667648 | E1760: =LN('Data Daily'!E1760/'Data Daily'!E1759) -> -0.010903214 | F1760: =LN('Data Daily'!F1760/'Data Daily'!F1759) -> -0.013779746 | G1760: =LN('Data Daily'!G1760/'Data Daily'!G1759) -> -0.029730334 | H1760: =LN('Data Daily'!H1760/'Data Daily'!H1759) -> -0.013501391 | I1760: =LN('Data Daily'!I1760/'Data Daily'!I1759) -> -0.02256074 | ... U1760: =LN('Data Daily'!U1760/'Data Daily'!U1759) -> -0.00041972718 | AZ1760: 46279 | BA1760: 1.1549 | BB1760: 0.85549 | BC1760: 178.25
AZ1761: 46280 | BA1761: 1.1544 | BB1761: 0.85644 | BC1761: 179.04
A1762: Mean D Returns | B1762: =AVERAGE(B9:B1760) -> 5.0096788e-05 | C1762: =AVERAGE(C9:C1760) -> 0.00019503914 | D1762: =AVERAGE(D9:D1760) -> 0.00030981404 | E1762: =AVERAGE(E9:E1760) -> 0.00022456462 | F1762: =AVERAGE(F9:F1760) -> -0.00011381765 | G1762: =AVERAGE(G9:G1760) -> 0.00036841537 | H1762: =AVERAGE(H9:H1760) -> 8.9735645e-05 | I1762: =AVERAGE(I9:I1760) -> 5.40536e-05 | ... U1762: =AVERAGE(U9:U1760) -> 0.00053977501 | AZ1762: 46281 | BA1762: 1.1465 | BB1762: 0.85682 | BC1762: 179.15
A1763: Mean ann Returns | B1763: =B1762*250 -> 0.012524197 | C1763: =C1762*250 -> 0.048759785 | D1763: =D1762*250 -> 0.07745351 | E1763: =E1762*250 -> 0.056141154 | F1763: =F1762*250 -> -0.028454413 | G1763: =G1762*250 -> 0.092103843 | H1763: =H1762*250 -> 0.022433911 | I1763: =I1762*250 -> 0.0135134 | ... U1763: =U1762*250 -> 0.13494375 | AZ1763: 46282 | BA1763: 1.1476 | BB1763: 0.85904 | BC1763: 179.01
...
