Workbook

Sheet Working Model
A1: Last Modified 2/23/2026 | J1: Meta Inc. | S1: Mohanad Assali
A2: Main
F3: Capital Structure | H3: Price | I3: 639
H4: Shares outstanding | I4: 2565
H5: MC | I5: =I4*I3 -> 1639035
H6: Cash | I6: 81592 | J6: Q425
H7: Debt | I7: 58744 | J7: Q425
H8: EV | I8: =I5+I7-I6 -> 1616187 | J8: company doesn’t carry debt
D11: Quartely | S11: Annually | Y11: Projections
A12: Financial Statements
C13: $mil | D13: Q123 | E13: Q223 | F13: Q323 | G13: Q423 | H13: Q124 | I13: Q224 | J13: Q324 | K13: Q424 | L13: Q125 | M13: Q225 | N13: Q325 | O13: Q425 | P13: Q126 | S13: FY2020 | T13: FY2021 | U13: FY2022 | V13: FY2023 | W13: FY2024 | X13: FY2025 | Y13: FY2026 | Z13: FY2027 | AA13: FY2028 | AB13: FY2029 | AC13: FY2030
D14: 31/03/23 | E14: 30/06/23 | F14: 30/09/23 | G14: 31/12/23 | H14: 31/03/24 | I14: 30/06/24 | J14: 30/09/24 | K14: 31/12/24 | L14: 31/03/25 | M14: 30/06/25 | N14: 30/09/25 | O14: 31/12/25 | P14: 31/03/26 | S14: 31/12/20 | T14: 31/12/21 | U14: 31/12/22 | V14: 31/12/23 | W14: 31/12/24 | X14: 31/12/25 | Y14: 31/12/2026 | Z14: 31/12/2027 | AA14: 31/12/2028 | AB14: 31/12/2029 | AC14: 31/12/2030
A15: Income Statement
C17: Net Revenue | D17: 28645 | E17: 31999 | F17: 34146 | G17: 40111 | H17: 36455 | I17: 39071 | J17: 40589 | K17: 48385 | L17: 42314 | M17: 47516 | N17: 51242 | O17: 59893 | P17: 55000 | R17: 70697 | S17: 85965 | T17: 117929 | U17: 116609 | V17: =SUM(D17:G17) -> 134901 | W17: =SUM(H17:K17) -> 164500 | X17: =SUM(L17:O17) -> 200965 | Y17: =Inputs!E10 -> 241158 | Z17: =Inputs!F10 -> 277331.7 | AA17: =Inputs!G10 -> 305064.87 | AB17: =Inputs!H10 -> 329470.06 | AC17: =Inputs!I10 -> 349238.26
C18: COGS | D18: 6108 | E18: 5945 | F18: 6210 | G18: 7696 | H18: 6640 | I18: 7308 | J18: 7375 | K18: 8839 | L18: 7572 | M18: 8491 | N18: 9206 | O18: 10906 | P18: (10-k) | S18: 16692 | T18: 22649 | U18: 25249 | V18: 25959 | W18: 30161 | X18: 36175 | Y18: =Y17*Inputs!$E$15 -> 60289.5 | Z18: =Z17*Inputs!$E$15 -> 69332.925 | AA18: =AA17*Inputs!$E$15 -> 76266.217 | AB18: =AB17*Inputs!$E$15 -> 82367.515 | AC18: =AC17*Inputs!$E$15 -> 87309.566
C19: Gross Profit | D19: =D17-D18 -> 22537 | E19: =E17-E18 -> 26054 | F19: =F17-F18 -> 27936 | G19: =G17-G18 -> 32415 | H19: =H17-H18 -> 29815 | I19: =I17-I18 -> 31763 | J19: =J17-J18 -> 33214 | K19: =K17-K18 -> 39546 | ... O19: =O17-O18 -> 48987 | S19: =S17-S18 -> 69273 | T19: =T17-T18 -> 95280 | U19: =U17-U18 -> 91360 | V19: =V17-V18 -> 108942 | W19: =W17-W18 -> 134339 | X19: =X17-X18 -> 164790 | Y19: =Y17-Y18 -> 180868.5 | Z19: =Z17-Z18 -> 207998.77 | ... AC19: =AC17-AC18 -> 261928.7
C20: R&D | D20: 9381 | E20: 9344 | F20: 9241 | G20: 10517 | H20: 9978 | I20: 10537 | J20: 11177 | K20: 12180 | L20: 11458 | M20: 12942 | N20: 14043 | O20: 17136 | S20: 18447 | T20: 24655 | U20: 35338 | V20: 38483 | W20: 43873 | X20: 57372 | Y20: =Y17*Inputs!$E$16 -> 72347.4 | Z20: =Z17*Inputs!$E$16 -> 83199.51 | AA20: =AA17*Inputs!$E$16 -> 91519.461 | AB20: =AB17*Inputs!$E$16 -> 98841.018 | AC20: =AC17*Inputs!$E$16 -> 104771.48
C21: SG&A | D21: 5930 | E21: 7318 | F21: 4947 | G21: 5515 | H21: 6019 | I21: 6379 | J21: 4687 | K21: 4003 | L21: 5729 | M21: 5642 | N21: 7458 | O21: 7107 | S21: 20203 | T21: 22112 | U21: 27078 | V21: 23709 | W21: 21087 | X21: 24143 | Y21: =Y17*Inputs!$E$17 -> 28938.96 | Z21: =Z17*Inputs!$E$17 -> 33279.804 | AA21: =AA17*Inputs!$E$17 -> 36607.784 | AB21: =AB17*Inputs!$E$17 -> 39536.407 | AC21: =AC17*Inputs!$E$17 -> 41908.592
C22: Operating expenses | D22: =SUM(D20:D21) -> 15311 | E22: =SUM(E20:E21) -> 16662 | F22: =SUM(F20:F21) -> 14188 | G22: =SUM(G20:G21) -> 16032 | H22: =SUM(H20:H21) -> 15997 | I22: =SUM(I20:I21) -> 16916 | J22: =SUM(J20:J21) -> 15864 | K22: =SUM(K20:K21) -> 16183 | ... O22: =SUM(O20:O21) -> 24243 | S22: =SUM(S20:S21) -> 38650 | T22: =SUM(T20:T21) -> 46767 | U22: =SUM(U20:U21) -> 62416 | V22: =SUM(V20:V21) -> 62192 | W22: =SUM(W20:W21) -> 64960 | X22: =SUM(X20:X21) -> 81515 | Y22: =SUM(Y20:Y21) -> 101286.36 | Z22: =SUM(Z20:Z21) -> 116479.31 | ... AC22: =SUM(AC20:AC21) -> 146680.07
C23: Operating Income (EBIT) | D23: =D19-D22 -> 7226 | E23: =E19-E22 -> 9392 | F23: =F19-F22 -> 13748 | G23: =G19-G22 -> 16383 | H23: =H19-H22 -> 13818 | I23: =I19-I22 -> 14847 | J23: =J19-J22 -> 17350 | K23: =K19-K22 -> 23363 | ... O23: =O19-O22 -> 24744 | S23: =S19-S22 -> 30623 | T23: =T19-T22 -> 48513 | U23: =U19-U22 -> 28944 | V23: =V19-V22 -> 46750 | W23: =W19-W22 -> 69379 | X23: =X19-X22 -> 83275 | Y23: =Y19-Y22 -> 79582.14 | Z23: =Z19-Z22 -> 91519.461 | ... AC23: =AC19-AC22 -> 115248.63
C24: Interest exp | D24: 80 | E24: 113 | F24: 272 | G24: 424 | H24: 365 | I24: 259 | J24: 472 | K24: 188 | L24: 827 | M24: 93 | N24: 1128 | O24: 608 | S24: -502 | T24: -523 | U24: -276 | V24: 1089 | W24: 1284 | X24: 2656 | Y24: 700 | Z24: 700 | AA24: 700 | AB24: 700 | AC24: 700
C25: Pretax Income | D25: =SUM(D23:D24) -> 7306 | E25: =SUM(E23:E24) -> 9505 | F25: =SUM(F23:F24) -> 14020 | G25: =SUM(G23:G24) -> 16807 | H25: =SUM(H23:H24) -> 14183 | I25: =SUM(I23:I24) -> 15106 | J25: =SUM(J23:J24) -> 17822 | K25: =SUM(K23:K24) -> 23551 | ... O25: =SUM(O23:O24) -> 25352 | S25: =SUM(S23:S24) -> 30121 | T25: =SUM(T23:T24) -> 47990 | U25: =SUM(U23:U24) -> 28668 | V25: =SUM(V23:V24) -> 47839 | W25: =SUM(W23:W24) -> 70663 | X25: =SUM(X23:X24) -> 85931 | Y25: =SUM(Y23:Y24) -> 80282.14 | Z25: =SUM(Z23:Z24) -> 92219.461 | ... AC25: =SUM(AC23:AC24) -> 115948.63
C26: Tax | D26: 1598 | E26: 1717 | F26: 2437 | G26: 2791 | H26: 1814 | I26: 1641 | J26: 2134 | K26: 2715 | L26: 1738 | M26: 2197 | N26: 18954 | O26: 2586 | S26: 4027 | T26: 7906 | U26: 6020 | V26: 6564 | W26: 5736 | X26: 20162 | Y26: =Y25*0.15 -> 12042.321 | Z26: =Z25*0.15 -> 13832.919 | AA26: =AA25*0.15 -> 15205.711 | AB26: =AB25*0.15 -> 16413.768 | AC26: =AC25*0.15 -> 17392.294
C27: Net Income | D27: =D25-D26 -> 5708 | E27: =E25-E26 -> 7788 | F27: =F25-F26 -> 11583 | G27: =G25-G26 -> 14016 | H27: =H25-H26 -> 12369 | I27: =I25-I26 -> 13465 | J27: =J25-J26 -> 15688 | K27: =K25-K26 -> 20836 | ... O27: =O25-O26 -> 22766 | S27: =S25-S26 -> 26094 | T27: =T25-T26 -> 40084 | U27: =U25-U26 -> 22648 | V27: =V25-V26 -> 41275 | W27: =W25-W26 -> 64927 | X27: =X25-X26 -> 65769 | Y27: =Y25-Y26 -> 68239.819 | Z27: =Z25-Z26 -> 78386.542 | ... AC27: =AC25-AC26 -> 98556.333
C28: EPS | D28: =D27/D29 -> 2.1996146 | E28: =E27/E29 -> 2.9804822 | F28: =F27/F29 -> 4.3858387 | G28: =G27/G29 -> 5.3292776 | H28: =H27/H29 -> 4.7102056 | I28: =I27/I29 -> 5.1609812 | J28: =J27/J29 -> 6.0338462 | K28: =K27/K29 -> 8.0169296 | ... O28: =O27/O29 -> 8.8756335 | S28: =S27/S29 -> 9.0321911 | T28: =T27/T29 -> 14.020287 | U28: =U27/U29 -> 8.3881481 | V28: =V27/V29 -> 15.693916 | W28: =W27/W29 -> 24.838179 | X28: =X27/X29 -> 25.551282 | Y28: =Y27/Y29 -> 26.604218 | Z28: =Z27/Z29 -> 30.560055 | ... AC28: =AC27/AC29 -> 38.423522
C29: Shares Outstanding | D29: 2595 | E29: 2613 | F29: 2641 | G29: 2630 | H29: 2626 | I29: 2609 | J29: 2600 | K29: 2599 | L29: 2588 | M29: 2568 | N29: 2580 | O29: 2565 | S29: 2889 | T29: 2859 | U29: 2700 | V29: 2630 | W29: 2614 | X29: 2574 | Y29: =Inputs!E21 -> 2565 | Z29: =Y29 -> 2565 | AA29: =Z29 -> 2565 | AB29: =AA29 -> 2565 | AC29: =AB29 -> 2565
A31: Financial Ratios | F31: Revenue Growth y/y | H31: =H17/D17-1 -> 0.27264793 | I31: =I17/E17-1 -> 0.22100691 | J31: =J17/F17-1 -> 0.18868974 | K31: =K17/G17-1 -> 0.20627758 | L31: =L17/H17-1 -> 0.16071869 | M31: =M17/I17-1 -> 0.21614497 | N31: =N17/J17-1 -> 0.26246027 | O31: =O17/K17-1 -> 0.23784231 | S31: =S17/R17-1 -> 0.2159639 | T31: =T17/S17-1 -> 0.37182574 | U31: =U17/T17-1 -> -0.011193176 | V31: =V17/U17-1 -> 0.15686611 | W31: =W17/V17-1 -> 0.21941275 | X31: =X17/W17-1 -> 0.22167173
F32: Gross Margin | H32: =H19/H17 -> 0.81785763 | I32: =I19/I17 -> 0.8129559 | J32: =J19/J17 -> 0.81830052 | K32: =K19/K17 -> 0.81731942 | L32: =L19/L17 -> 0.82105213 | M32: =M19/M17 -> 0.8213023 | N32: =N19/N17 -> 0.82034269 | O32: =O19/O17 -> 0.8179086 | P32: GP/Revenue | S32: =S19/S17 -> 0.80582795 | T32: =T19/T17 -> 0.80794376 | U32: =U19/U17 -> 0.78347297 | V32: =V19/V17 -> 0.80757 | W32: =W19/W17 -> 0.81665046 | X32: =X19/X17 -> 0.81999353
F33: Operating Margin | H33: =H23/H17 -> 0.37904266 | I33: =I23/I17 -> 0.38000051 | J33: =J23/J17 -> 0.42745571 | K33: =K23/K17 -> 0.48285626 | L33: =L23/L17 -> 0.41487451 | M33: =M23/M17 -> 0.43019194 | N33: =N23/N17 -> 0.40074548 | O33: =O23/O17 -> 0.41313676 | P33: EBITDA/Revenue | S33: =S23/S17 -> 0.35622637 | T33: =T23/T17 -> 0.41137464 | U33: =U23/U17 -> 0.24821412 | V33: =V23/V17 -> 0.34655043 | W33: =W23/W17 -> 0.42175684 | X33: =X23/X17 -> 0.41437564
F34: RD% of Revenue | H34: =H20/H17 -> 0.27370731 | I34: =I20/I17 -> 0.26968852 | J34: =J20/J17 -> 0.27537017 | K34: =K20/K17 -> 0.25173091 | L34: =L20/L17 -> 0.27078508 | M34: =M20/M17 -> 0.27237141 | N34: =N20/N17 -> 0.27405254 | O34: =O20/O17 -> 0.28611023 | S34: =S20/S17 -> 0.21458733 | T34: =T20/T17 -> 0.20906647 | U34: =U20/U17 -> 0.30304693 | V34: =V20/V17 -> 0.28526846 | W34: =W20/W17 -> 0.26670517 | X34: =X20/X17 -> 0.28548255
F35: SG&D% of Revenue | H35: =H21/H17 -> 0.16510767 | I35: =I21/I17 -> 0.16326687 | J35: =J21/J17 -> 0.11547464 | K35: =K21/K17 -> 0.082732252 | L35: =L21/L17 -> 0.13539254 | M35: =M21/M17 -> 0.11873895 | N35: =N21/N17 -> 0.14554467 | O35: =O21/O17 -> 0.11866161 | S35: =S21/S17 -> 0.23501425 | T35: =T21/T17 -> 0.18750265 | U35: =U21/U17 -> 0.23221192 | V35: =V21/V17 -> 0.17575111 | W35: =W21/W17 -> 0.12818845 | X35: =X21/X17 -> 0.12013535
F36: COGS Margin | H36: =H18/H17 -> 0.18214237 | I36: =I18/I17 -> 0.1870441 | J36: =J18/J17 -> 0.18169948 | K36: =K18/K17 -> 0.18268058 | L36: =L18/L17 -> 0.17894787 | M36: =M18/M17 -> 0.1786977 | N36: =N18/N17 -> 0.17965731 | O36: =O18/O17 -> 0.1820914 | S36: =S18/S17 -> 0.19417205 | T36: =T18/T17 -> 0.19205624 | U36: =U18/U17 -> 0.21652703 | V36: =V18/V17 -> 0.19243 | W36: =W18/W17 -> 0.18334954 | X36: =X18/X17 -> 0.18000647
A39: Balance Sheet | C39: Cash | D39: =11551+25888 -> 37439 | E39: =28785+24661 -> 53446 | F39: =36890+24233 -> 61123 | G39: 65403 | H39: 58123 | I39: 58080 | J39: 70330 | K39: =43889+33926 -> 77815 | L39: 70230 | M39: 47070 | N39: 44450 | O39: 81592 | S39: 61954 | T39: 48000 | U39: 40740 | V39: 65403 | W39: =43889+33926 -> 77815 | X39: 81592
A40: Assets | C40: A/R | D40: 11044 | E40: 12511 | F40: 12944 | G40: 14832 | H40: 13430 | I40: 14505 | J40: 14700 | K40: 16994 | L40: 14514 | M40: 16561 | N40: 17297 | O40: 19769 | S40: 11335 | T40: 14039 | U40: 13466 | V40: 16169 | W40: 16994 | X40: 19769
C41: OCA | D41: 4000 | E41: 3603 | F41: 4311 | G41: 6027 | H41: 3780 | I41: 5765 | J41: 5950 | K41: 5236 | L41: 5483 | M41: 6159 | N41: 7203 | O41: 7361 | S41: 2381 | T41: 4627 | U41: 5343 | V41: 3793 | W41: 5236 | X41: 7361
C42: Current Assets | D42: =SUM(D39:D41) -> 52483 | E42: =SUM(E39:E41) -> 69560 | F42: =SUM(F39:F41) -> 78378 | G42: =SUM(G39:G41) -> 86262 | H42: =SUM(H39:H41) -> 75333 | I42: =SUM(I39:I41) -> 78350 | J42: =SUM(J39:J41) -> 90980 | K42: =SUM(K39:K41) -> 100045 | ... O42: =SUM(O39:O41) -> 108722 | S42: =SUM(S39:S41) -> 75670 | T42: =SUM(T39:T41) -> 66666 | U42: =SUM(U39:U41) -> 59549 | V42: =SUM(V39:V41) -> 85365 | W42: =SUM(W39:W41) -> 100045 | X42: =SUM(X39:X41) -> 108722
C43: Non-marketable equity invest. | D43: 6167 | E43: 6208 | F43: 6142 | G43: 7120 | H43: 6218 | I43: 6045 | J43: 6060 | K43: 6070 | L43: 6168 | M43: 14500 | N43: 25120 | O43: 27524 | S43: 6234 | T43: 6775 | U43: 6201 | V43: 6141 | W43: 6070 | X43: 27524
C44: PPE | D44: 84156 | E44: 87949 | F44: 91772 | G44: 81500 | H44: 98908 | I44: 102959 | J44: 112162 | K44: 121346 | L44: 133567 | M44: 147039 | N44: 160270 | O44: 176400 | S44: 45633 | T44: 57809 | U44: 79518 | V44: 96587 | W44: 121346 | X44: 176400
C45: operating lease | D45: =12899 -> 12899 | E45: 12955 | F45: 13033 | G45: 10802 | H45: 13555 | I45: 14105 | J45: 14500 | K45: 14922 | L45: 15505 | M45: 16800 | N45: 18540 | O45: 20404 | S45: 9348 | T45: 12155 | U45: 12640 | V45: 13294 | W45: 14922 | X45: 20404
C46: Goodwill | D46: =949+20649 -> 21598 | E46: =20659+856 -> 21515 | F46: =20668+813 -> 21481 | G46: 20654 | H46: 20654 | I46: 20654 | J46: 20654 | K46: 20654 | L46: 20654 | M46: 20654 | N46: 21158 | O46: 24534 | S46: =19050+623 -> 19673 | T46: =19197+634 -> 19831 | U46: 20306 | V46: 20654 | W46: 20654 | X46: 24534
...

Sheet Inputs
A2: Inputs
C7: Assumptions/Inputs | J7: Guidance/Notes
D8: FY2025A | E8: FY2026 | F8: FY2027 | G8: FY2028 | H8: FY2029 | I8: FY2030
A10: Growth & Revenue | C10: Revenue | E10: ='Working Model'!X17*(1+Inputs!E11) -> 241158 | F10: =E10*(1+F11) -> 277331.7 | G10: =F10*(1+G11) -> 305064.87 | H10: =G10*(1+H11) -> 329470.06 | I10: =H10*(1+I11) -> 349238.26
C11: %Revenue | E11: 0.2 | F11: 0.15 | G11: 0.1 | H11: 0.08 | I11: 0.06 | J11: Meta guided Q126 at 30%. Over 20% is JPM Guidance | K11: ‎
C13: Long term growth rate (g) | E13: 0.025 | F13: =E13 -> 0.025 | G13: =F13 -> 0.025 | H13: =G13 -> 0.025 | I13: =H13 -> 0.025
A15: Expenses | C15: COGS | E15: 0.25 | J15: COGS is usually 18-20% of revenue. Mark zuckerberg projects atleast 163B in spending (AI Infrastructure), Elevated to 25% to account for higher energy and maintenance costs associated with AI infrastructure | K15: ‎
C16: R&D | E16: 0.3 | J16: Maintained at 30% to reflect Meta's ongoing commitment to open-source AI | K16: ‎
C17: SG&A | E17: 0.12 | J17: Stabilized at 12% following 'Year of Efficiency' restructuring | K17: ‎
C18: Tax Rate | E18: 0.15 | J18: 15% based on management guidance of 13%–16% for FY2026 | K18: ‎
A20: Capital Structure | C20: WAAC | E20: =#REF! -> #REF!
C21: Shares Outstanding | E21: ='Working Model'!I4 -> 2565
K23: ‎
A24: Capex - D&A | C24: Capex | D24: 72000 | E24: 120000 | F24: 100000 | G24: 90000 | H24: 60000 | I24: 45000 | J24: Guidance for 2026 is $115B–$135B. I expect that to continue for the next till 2028 | K24: ‎
C25: D&A | D25: ='Working Model'!X63 -> 18616 | E25: 30000 | F25: 42000 | G25: 55000 | H25: 65000 | I25: 55000 | J25: META Servers useful life at 5.5yrs - Look at Meta 2024 Report Page 1, Footnote1 --- https://investor.atmeta.com/investor-news/press-release-details/2025/Meta-Reports-Fourth-Quarter-and-Full-Year-2024-Results/ | K25: ‎
K26: ‎
A27: Valuation | C27: EBITDA Multiple | E27: 14 | J27: 14.0x selected as a conservative mid-point vs. peer median (14.8x) | K27: ‎
C28: Net Working Capital | E28: 0.05 | P28: One "Trap" to Watch Out For
P29: In your Expenses section, you have the percentages (COGS 25%, R&D 30%, SG&A 12%).
P30: The Math: $25 + 30 + 12 = 67\%$.
P31: The Result: This implies an Operating Margin (EBIT) of 33%.
P32: The Jury Question: "Why is your margin 33% when Meta just reported 41% in 2024?"
P33: Your Answer: "We are modeling a 'Margin Compression' scenario due to the massive energy and compute costs of AI. We chose to be conservative to ensure our $684 price target is sustainable even if AI costs are higher than expected."

Sheet Notes
A2: Notes
D8: (10-K) Report | E8: https://www.sec.gov/Archives/edgar/data/1326801/000162828026003942/meta-20251231.htm | F8: ‎
E9: https://investor.atmeta.com/investor-news/default.aspx | F9: ‎
