Workbook
Name Inv_Cap: [1]Results!$E$182:$AD$182
Name NOPLAT: [1]Results!$E$145:$AD$145
Name One: '[1]Forecast Drivers'!$D$330
Name Products: [2]Array0!$B$5:$C$7
Name Rev: '[1]Forecast Drivers'!$E$25:$S$25

Sheet BoostToolkitClipBoard2010
A1: -12

Sheet Outputs
A1: last modified 1/27/2026 | H1: Comps Analysis | O1: Mohanad Assali
A2: Outputs
F8: Last Twelve Months (LTM) | K8: Year 1 Forecast - Calendar Year | P8: Year 2 Forecast - Calendar Year
B9: Ticker | C9: Market capitalization (mm) | D9: Enterprise value (EV) | F9: Revenues | G9: EBITDA | H9: EBIT | I9: EPS | K9: Revenues | L9: EBITDA | M9: EBIT | N9: EPS | P9: Revenues | Q9: EBITDA | R9: EBIT | S9: EPS | T9: LT growth rate
B11: =Inputs!E$8 -> PEP | C11: =Inputs!E19*Inputs!E11 -> 201711.4 | D11: =Inputs!E135+Inputs!E127 -> 241929.4 | F11: =Inputs!E25+Inputs!E43-Inputs!E61 -> 93064 | G11: =Inputs!E40+Inputs!E58-Inputs!E76 -> 18042 | H11: =Inputs!E30+Inputs!E48-Inputs!E66 -> 15227 | I11: =Inputs!E37+Inputs!E55-Inputs!E73 -> 7.93 | K11: =Inputs!E99 -> 98280 | L11: =Inputs!E100 -> 16850 | M11: =Inputs!E101 -> 13970 | N11: =Inputs!E102 -> 8.75 | P11: =Inputs!E108 -> 102150 | Q11: =Inputs!E109 -> 17920 | R11: =Inputs!E110 -> 14940 | S11: =Inputs!E111 -> 9.65 | T11: =Inputs!E116 -> 0.057
B12: =Inputs!F$8 -> KDP | C12: =Inputs!F19*Inputs!F11 -> 38032.8 | D12: =Inputs!F135+Inputs!F127 -> 53478.8 | F12: =Inputs!F25+Inputs!F43-Inputs!F61 -> 15500 | G12: =Inputs!F40+Inputs!F58-Inputs!F76 -> 3738 | H12: =Inputs!F30+Inputs!F48-Inputs!F66 -> 2681 | I12: =Inputs!F37+Inputs!F55-Inputs!F73 -> 1.14 | K12: =Inputs!F99 -> 16425 | L12: =Inputs!F100 -> 4010 | M12: =Inputs!F101 -> 2950 | N12: =Inputs!F102 -> 2.25 | P12: =Inputs!F108 -> 17110 | Q12: =Inputs!F109 -> 4245 | R12: =Inputs!F110 -> 3150 | S12: =Inputs!F111 -> 2.48 | T12: =Inputs!F116 -> 0.042
B13: =Inputs!G$8 -> MNST | C13: =Inputs!G19*Inputs!G11 -> 81081 | D13: =Inputs!G135+Inputs!G127 -> 78091 | F13: =Inputs!G25+Inputs!G43-Inputs!G61 -> 7583 | G13: =Inputs!G40+Inputs!G58-Inputs!G76 -> 2083 | H13: =Inputs!G30+Inputs!G48-Inputs!G66 -> 1976 | I13: =Inputs!G37+Inputs!G55-Inputs!G73 -> 1.52 | K13: =Inputs!G99 -> 8610 | L13: =Inputs!G100 -> 2410 | M13: =Inputs!G101 -> 2240 | N13: =Inputs!G102 -> 1.85 | P13: =Inputs!G108 -> 9340 | Q13: =Inputs!G109 -> 2695 | R13: =Inputs!G110 -> 2510 | S13: =Inputs!G111 -> 2.05 | T13: =Inputs!G116 -> 0.168
B14: =Inputs!H$8 -> CELH | C14: =Inputs!H19*Inputs!H11 -> 16238.352 | D14: =Inputs!H135+Inputs!H127 -> 17155.252 | F14: =Inputs!H25+Inputs!H43-Inputs!H61 -> 1342 | G14: =Inputs!H40+Inputs!H58-Inputs!H76 -> -46 | H14: =Inputs!H30+Inputs!H48-Inputs!H66 -> -79 | I14: =Inputs!H37+Inputs!H55-Inputs!H73 -> 0.36 | K14: =Inputs!H99 -> 3610 | L14: =Inputs!H100 -> 485 | M14: =Inputs!H101 -> 395 | N14: =Inputs!H102 -> 1.15 | P14: =Inputs!H108 -> 4080 | Q14: =Inputs!H109 -> 610 | R14: =Inputs!H110 -> 520 | S14: =Inputs!H111 -> 1.95 | T14: =Inputs!H116 -> 0.362
F16: Last Twelve Months (LTM) | K16: Year 1 Forecast - Calendar Year | P16: Year 2 Forecast - Calendar Year
B17: Ticker | F17: EV / Revenues | G17: EV / EBITDA | H17: EV / EBIT | I17: P/E | K17: EV / Revenues | L17: EV / EBITDA | M17: EV / EBIT | N17: P/E | P17: EV / Revenues | Q17: EV / EBITDA | R17: EV / EBIT | S17: P/E | T17: PEG ratio
B19: =Inputs!E$8 -> PEP | F19: =Inputs!E138/Inputs!E81 -> 2.5996024 | G19: =Inputs!E138/Inputs!E82 -> 13.409234 | H19: =Inputs!E138/Inputs!E83 -> 15.888185 | I19: =Inputs!E11/Inputs!E84 -> 18.3657 | K19: =Inputs!E$138/Inputs!E99 -> 2.4616341 | L19: =Inputs!E$138/Inputs!E100 -> 14.357828 | M19: =Inputs!E$138/Inputs!E101 -> 17.317781 | N19: =Inputs!E133/Inputs!E102 -> 16.644571 | P19: =Inputs!E$138/Inputs!E108 -> 2.368374 | Q19: =Inputs!E$138/Inputs!E109 -> 13.500525 | R19: =Inputs!E$138/Inputs!E110 -> 16.1934 | S19: =Inputs!E133/Inputs!E111 -> 15.092228 | T19: =Inputs!E151/(Inputs!E116*100) -> 2.9201003
B20: =Inputs!F$8 -> KDP | F20: =Inputs!F138/Inputs!F81 -> 3.4502452 | G20: =Inputs!F138/Inputs!F82 -> 14.306795 | H20: =Inputs!F138/Inputs!F83 -> 19.947333 | I20: =Inputs!F11/Inputs!F84 -> 24.175439 | K20: =Inputs!F$138/Inputs!F99 -> 3.2559391 | L20: =Inputs!F$138/Inputs!F100 -> 13.336359 | M20: =Inputs!F$138/Inputs!F101 -> 18.128407 | N20: =Inputs!F133/Inputs!F102 -> 12.248889 | P20: =Inputs!F$138/Inputs!F108 -> 3.1255874 | Q20: =Inputs!F$138/Inputs!F109 -> 12.598068 | R20: =Inputs!F$138/Inputs!F110 -> 16.977397 | S20: =Inputs!F133/Inputs!F111 -> 11.112903 | T20: =Inputs!F151/(Inputs!F116*100) -> 2.9164021
B21: =Inputs!G$8 -> MNST | F21: =Inputs!G138/Inputs!G81 -> 10.298167 | G21: =Inputs!G138/Inputs!G82 -> 37.489678 | H21: =Inputs!G138/Inputs!G83 -> 39.519737 | I21: =Inputs!G11/Inputs!G84 -> 53.881579 | K21: =Inputs!G$138/Inputs!G99 -> 9.0698026 | L21: =Inputs!G$138/Inputs!G100 -> 32.402905 | M21: =Inputs!G$138/Inputs!G101 -> 34.862054 | N21: =Inputs!G133/Inputs!G102 -> 44.27027 | P21: =Inputs!G$138/Inputs!G108 -> 8.3609208 | Q21: =Inputs!G$138/Inputs!G109 -> 28.976252 | R21: =Inputs!G$138/Inputs!G110 -> 31.111952 | S21: =Inputs!G133/Inputs!G111 -> 39.95122 | T21: =Inputs!G151/(Inputs!G116*100) -> 2.6351351
B22: =Inputs!H$8 -> CELH | F22: =Inputs!H138/Inputs!H81 -> 12.783347 | G22: =Inputs!H138/Inputs!H82 -> -372.94026 | H22: =Inputs!H138/Inputs!H83 -> -217.15509 | I22: =Inputs!H11/Inputs!H84 -> 153.11111 | K22: =Inputs!H$138/Inputs!H99 -> 4.7521474 | L22: =Inputs!H$138/Inputs!H100 -> 35.371654 | M22: =Inputs!H$138/Inputs!H101 -> 43.431018 | N22: =Inputs!H133/Inputs!H102 -> 47.930435 | P22: =Inputs!H$138/Inputs!H108 -> 4.2047186 | Q22: =Inputs!H$138/Inputs!H109 -> 28.123364 | R22: =Inputs!H$138/Inputs!H110 -> 32.990869 | S22: =Inputs!H133/Inputs!H111 -> 28.266667 | T22: =Inputs!H151/(Inputs!H116*100) -> 1.3240452
E24: High | F24: =MAX(F19:F22) -> 12.783347 | G24: =MAX(G19:G22) -> 37.489678 | H24: =MAX(H19:H22) -> 39.519737 | I24: =MAX(I19:I22) -> 153.11111 | K24: =MAX(K19:K22) -> 9.0698026 | L24: =MAX(L19:L22) -> 35.371654 | M24: =MAX(M19:M22) -> 43.431018 | N24: =MAX(N19:N22) -> 47.930435 | P24: =MAX(P19:P22) -> 8.3609208 | Q24: =MAX(Q19:Q22) -> 28.976252 | R24: =MAX(R19:R22) -> 32.990869 | S24: =MAX(S19:S22) -> 39.95122 | T24: =MAX(T19:T22) -> 2.9201003
E25: Low | F25: =MIN(F19:F22) -> 2.5996024 | G25: =MIN(G19:G22) -> -372.94026 | H25: =MIN(H19:H22) -> -217.15509 | I25: =MIN(I19:I22) -> 18.3657 | K25: =MIN(K19:K22) -> 2.4616341 | L25: =MIN(L19:L22) -> 13.336359 | M25: =MIN(M19:M22) -> 17.317781 | N25: =MIN(N19:N22) -> 12.248889 | P25: =MIN(P19:P22) -> 2.368374 | Q25: =MIN(Q19:Q22) -> 12.598068 | R25: =MIN(R19:R22) -> 16.1934 | S25: =MIN(S19:S22) -> 11.112903 | T25: =MIN(T19:T22) -> 1.3240452
E26: Median | F26: =MEDIAN(F19:F22) -> 6.8742061 | G26: =MEDIAN(G19:G22) -> 13.858015 | H26: =MEDIAN(H19:H22) -> 17.917759 | I26: =MEDIAN(I19:I22) -> 39.028509 | K26: =MEDIAN(K19:K22) -> 4.0040432 | L26: =MEDIAN(L19:L22) -> 23.380366 | M26: =MEDIAN(M19:M22) -> 26.49523 | N26: =MEDIAN(N19:N22) -> 30.457421 | P26: =MEDIAN(P19:P22) -> 3.665153 | Q26: =MEDIAN(Q19:Q22) -> 20.811944 | R26: =MEDIAN(R19:R22) -> 24.044675 | S26: =MEDIAN(S19:S22) -> 21.679447 | T26: =MEDIAN(T19:T22) -> 2.7757686
E27: Mean | F27: =AVERAGE(F19:F22) -> 7.2828404 | G27: =AVERAGE(G19:G22) -> -76.933638 | H27: =AVERAGE(H19:H22) -> -35.449958 | I27: =AVERAGE(I19:I22) -> 62.383457 | K27: =AVERAGE(K19:K22) -> 4.8848808 | L27: =AVERAGE(L19:L22) -> 23.867186 | M27: =AVERAGE(M19:M22) -> 28.434815 | N27: =AVERAGE(N19:N22) -> 30.273541 | P27: =AVERAGE(P19:P22) -> 4.5149002 | Q27: =AVERAGE(Q19:Q22) -> 20.799552 | R27: =AVERAGE(R19:R22) -> 24.318405 | S27: =AVERAGE(S19:S22) -> 23.605754 | T27: =AVERAGE(T19:T22) -> 2.4489207
E28: EXTR | F28: =F19 -> 2.5996024 | G28: =G19 -> 13.409234 | H28: =H19 -> 15.888185 | I28: =I19 -> 18.3657 | K28: =K19 -> 2.4616341 | L28: =L19 -> 14.357828 | M28: =M19 -> 17.317781 | N28: =N19 -> 16.644571 | P28: =P19 -> 2.368374 | Q28: =Q19 -> 13.500525 | R28: =R19 -> 16.1934 | S28: =S19 -> 15.092228 | T28: =T19 -> 2.9201003

Sheet Inputs
N1: Ticker | O1: Name
A2: Inputs | N2: PEP | O2: PepsiCo.
N3: KDP | O3: Keurig Dr Pepper
N4: MNST | O4: Monster
N5: CELH | O5: Celsius
E7: 1 | F7: 2 | G7: 3 | H7: 4 | I7: 5
A8: Market Data Inputs | C8: Ticker | E8: PEP | F8: KDP | G8: MNST | H8: CELH
C9: Date of latest filing | E9: 10/9/2025(Q3) | F9: 10/28/2025(Q3) | G9: 11/6/2025(Q3) | H9: 11/6/2025 (Q3)
C10: Date of latest fiscal year end (FYE) | E10: 45319 | F10: 45657 | G10: 45657 | H10: 45657
C11: Stock price on current date | E11: 145.64 | F11: 27.56 | G11: 81.9 | H11: 55.12
C12: Share price date | E12: 46048 | F12: 46048 | G12: 46048 | H12: 46048
A15: Shares Data | C15: Basic shares outstanding | E15: 1372 | F15: 1374 | G15: 985 | H15: 258
C16: Net shares from exercisable options | E16: 13 | F16: 6 | G16: 5 | H16: 5
C17: Total shares from convertible debt | E17: 0 | F17: 0 | G17: 0 | H17: 31.6
C18: Total shares from convertible preferred | E18: 0 | F18: 0 | G18: 0 | H18: 0
C19: Fully diluted shares | E19: =SUM(E15:E18) -> 1385 | F19: =SUM(F15:F18) -> 1380 | G19: =SUM(G15:G18) -> 990 | H19: =SUM(H15:H18) -> 294.6
A23: Financials
E24: =E$8 -> PEP | F24: =F$8 -> KDP | G24: =G$8 -> MNST | H24: =H$8 -> CELH | I24: =I$8 -> 0
A25: LAST FISCAL YEAR | C25: Revenues | E25: 91854 | F25: 15350 | G25: 7493 | H25: 1356
C26: COGS | E26: 41744 | F26: 6821 | G26: 3444 | H26: 676
C27: Gross Profit | E27: =E25-E26 -> 50110 | F27: =F25-F26 -> 8529 | G27: =G25-G26 -> 4049 | H27: =H25-H26 -> 680
C28: SG&A | E28: 37190 | F28: 4649 | G28: 2119 | H28: 518
C29: Other Expenses | E29: 33 | F29: 1300 | G29: 0 | H29: 17
C30: EBIT | E30: =E27-E28-E29 -> 12887 | F30: =F27-F28-F29 -> 2580 | G30: =G27-G28-G29 -> 1930 | H30: =H27-H28-H29 -> 145
C31: Interest expense | E31: -935 | F31: -550 | G31: 0 | H31: 0
C32: Non operating income | E32: 350 | F32: 55 | G32: 59 | H32: 22 | J32: =91854+23940-22730 -> 93064
C33: Non operating expense | E33: -352 | F33: -19 | G33: 0 | H33: -43
C34: Pretax income | E34: =SUM(E30:E33) -> 11950 | F34: =SUM(F30:F33) -> 2066 | G34: =SUM(G30:G33) -> 1989 | H34: =SUM(H30:H33) -> 124
C35: Taxes (Benefit) | E35: -2320 | F35: -666 | G35: -146.704 | H35: -19
C36: Net Income | E36: =SUM(E34:E35) -> 9630 | F36: =SUM(F34:F35) -> 1400 | G36: =SUM(G34:G35) -> 1842.296 | H36: =SUM(H34:H35) -> 105
C37: Diluted EPS | E37: 6.95 | F37: 1.05 | G37: 1.49 | H37: 0.45
C39: D&A | E39: -2800 | F39: -1050 | G39: -112 | H39: -32
C40: EBITDA | E40: =E30-E39 -> 15687 | F40: =F30-F39 -> 3630 | G40: =G30-G39 -> 2042 | H40: =H30-H39 -> 177
E42: =E$8 -> PEP | F42: =F$8 -> KDP | G42: =G$8 -> MNST | H42: =H$8 -> CELH | I42: =I$8 -> 0
A43: LAST QUARTER | C43: Revenues | E43: 23940 | F43: 4310 | G43: 2200 | H43: 725
C44: COGS | E44: 11140 | F44: 2155 | G44: 975 | H44: 353
C45: Gross Profit | E45: =E43-E44 -> 12800 | F45: =F43-F44 -> 2155 | G45: =G43-G44 -> 1225 | H45: =H43-H44 -> 372
C46: SG&A | E46: 8600 | F46: 1154 | G46: 549 | H46: 206
C47: Other Expenses | E47: 600 | F47: 2 | G47: 0 | H47: 247
C48: EBIT | E48: =E45-E46-E47 -> 3600 | F48: =F45-F46-F47 -> 999 | G48: =G45-G46-G47 -> 676 | H48: =H45-H46-H47 -> -81
...
